[06/Jul/2016 08:48:27] DEBUG [pinutcloud.views:223] INSIDE POST REQUEST
[06/Jul/2016 08:48:27] ERROR [django.request:284] Internal Server Error: /pinutcloud/dashboard/
Traceback (most recent call last):
  File "/home/ec2-user/Virtual_Env/pinut_env/local/lib/python2.7/site-packages/django/core/handlers/base.py", line 158, in get_response
    % (callback.__module__, view_name))
ValueError: The view pinutcloud.views.validatelogin didn't return an HttpResponse object. It returned None instead.
[06/Jul/2016 08:48:55] ERROR [django.request:284] Internal Server Error: /pinutcloud/dashboard/
Traceback (most recent call last):
  File "/home/ec2-user/Virtual_Env/pinut_env/local/lib/python2.7/site-packages/django/core/handlers/base.py", line 158, in get_response
    % (callback.__module__, view_name))
ValueError: The view pinutcloud.views.validatelogin didn't return an HttpResponse object. It returned None instead.
[06/Jul/2016 08:53:36] ERROR [django.request:284] Internal Server Error: /pinutcloud/dashboard/
Traceback (most recent call last):
  File "/home/ec2-user/Virtual_Env/pinut_env/local/lib/python2.7/site-packages/django/core/handlers/base.py", line 158, in get_response
    % (callback.__module__, view_name))
ValueError: The view pinutcloud.views.validatelogin didn't return an HttpResponse object. It returned None instead.
[06/Jul/2016 10:21:22] ERROR [django.request:284] Internal Server Error: /pinutcloud/dashboard/
Traceback (most recent call last):
  File "/home/ec2-user/Virtual_Env/pinut_env/local/lib/python2.7/site-packages/django/core/handlers/base.py", line 158, in get_response
    % (callback.__module__, view_name))
ValueError: The view pinutcloud.views.validatelogin didn't return an HttpResponse object. It returned None instead.
[06/Jul/2016 10:23:26] ERROR [django.request:284] Internal Server Error: /pinutcloud/dashboard/
Traceback (most recent call last):
  File "/home/ec2-user/Virtual_Env/pinut_env/local/lib/python2.7/site-packages/django/core/handlers/base.py", line 158, in get_response
    % (callback.__module__, view_name))
ValueError: The view pinutcloud.views.validatelogin didn't return an HttpResponse object. It returned None instead.
[06/Jul/2016 10:30:00] ERROR [django.request:284] Internal Server Error: /pinutcloud/dashboard/
Traceback (most recent call last):
  File "/home/ec2-user/Virtual_Env/pinut_env/local/lib/python2.7/site-packages/django/core/handlers/base.py", line 158, in get_response
    % (callback.__module__, view_name))
ValueError: The view pinutcloud.views.validatelogin didn't return an HttpResponse object. It returned None instead.
[06/Jul/2016 10:41:02] ERROR [django.request:284] Internal Server Error: /pinutcloud/dashboard/
Traceback (most recent call last):
  File "/home/ec2-user/Virtual_Env/pinut_env/local/lib/python2.7/site-packages/django/core/handlers/base.py", line 158, in get_response
    % (callback.__module__, view_name))
ValueError: The view pinutcloud.views.validatelogin didn't return an HttpResponse object. It returned None instead.
[06/Jul/2016 10:41:45] ERROR [django.request:284] Internal Server Error: /pinutcloud/dashboard/
Traceback (most recent call last):
  File "/home/ec2-user/Virtual_Env/pinut_env/local/lib/python2.7/site-packages/django/core/handlers/base.py", line 158, in get_response
    % (callback.__module__, view_name))
ValueError: The view pinutcloud.views.validatelogin didn't return an HttpResponse object. It returned None instead.
[06/Jul/2016 10:46:27] ERROR [pinutcloud.views:249] Exception : "'password'" 
[06/Jul/2016 11:41:19] ERROR [django.request:284] Internal Server Error: /pinutcloud/getTotalDownloads/
Traceback (most recent call last):
  File "/home/ec2-user/Virtual_Env/pinut_env/local/lib/python2.7/site-packages/django/core/handlers/base.py", line 149, in get_response
    response = self.process_exception_by_middleware(e, request)
  File "/home/ec2-user/Virtual_Env/pinut_env/local/lib/python2.7/site-packages/django/core/handlers/base.py", line 147, in get_response
    response = wrapped_callback(request, *callback_args, **callback_kwargs)
  File "/home/ec2-user/Virtual_Env/DjangoCloudCode/DjangoCloudCode/pinutcloud/views.py", line 99, in getTotalDownloads
    number_of_downloads = utility_script_user_intro.get_number_of_downloads(cust_name ,start_date_obj ,end_date_obj)
  File "/home/ec2-user/Virtual_Env/DjangoCloudCode/DjangoCloudCode/pinutcloud/analytics/utility_script_user_intro.py", line 27, in get_number_of_downloads
    logging.exception("Exception, in getting number of downloads from user intro data %s" % e)
TypeError: __str__ returned non-string (type InvalidName)
[06/Jul/2016 11:41:19] DEBUG [pinutcloud.views:37] Inside GET request
[06/Jul/2016 11:41:19] ERROR [django.request:284] Internal Server Error: /pinutcloud/getTotalFeedback/
Traceback (most recent call last):
  File "/home/ec2-user/Virtual_Env/pinut_env/local/lib/python2.7/site-packages/django/core/handlers/base.py", line 149, in get_response
    response = self.process_exception_by_middleware(e, request)
  File "/home/ec2-user/Virtual_Env/pinut_env/local/lib/python2.7/site-packages/django/core/handlers/base.py", line 147, in get_response
    response = wrapped_callback(request, *callback_args, **callback_kwargs)
  File "/home/ec2-user/Virtual_Env/DjangoCloudCode/DjangoCloudCode/pinutcloud/views.py", line 44, in getTotalFeedback
    number_of_feedbacks = utility_script_feedback.get_total_feedback(cust_name ,start_date_obj ,end_date_obj)
  File "/home/ec2-user/Virtual_Env/DjangoCloudCode/DjangoCloudCode/pinutcloud/analytics/utility_script_feedback.py", line 27, in get_total_feedback
    logging.exception("Exception, No feedback data %s" % e)
TypeError: __str__ returned non-string (type InvalidName)
[06/Jul/2016 11:41:19] DEBUG [pinutcloud.views:130] Inside processmongodata
[06/Jul/2016 11:41:19] DEBUG [pinutcloud.views:132] Inside GET request
[06/Jul/2016 11:41:19] ERROR [django.request:284] Internal Server Error: /pinutcloud/processUserInfoMongoData/
Traceback (most recent call last):
  File "/home/ec2-user/Virtual_Env/pinut_env/local/lib/python2.7/site-packages/django/core/handlers/base.py", line 149, in get_response
    response = self.process_exception_by_middleware(e, request)
  File "/home/ec2-user/Virtual_Env/pinut_env/local/lib/python2.7/site-packages/django/core/handlers/base.py", line 147, in get_response
    response = wrapped_callback(request, *callback_args, **callback_kwargs)
  File "/home/ec2-user/Virtual_Env/DjangoCloudCode/DjangoCloudCode/pinutcloud/views.py", line 139, in processUserInfoMongoData
    user_info_data = utility_script_user_info.get_data_per_location(cust_name ,start_date_obj ,end_date_obj)
  File "/home/ec2-user/Virtual_Env/DjangoCloudCode/DjangoCloudCode/pinutcloud/analytics/utility_script_user_info.py", line 124, in get_data_per_location
    lid_devicemac_dict = get_data_per_device(cust_name ,start_date_obj ,end_date_obj)
  File "/home/ec2-user/Virtual_Env/DjangoCloudCode/DjangoCloudCode/pinutcloud/analytics/utility_script_user_info.py", line 112, in get_data_per_device
    logging.exception("Exception, in processing data across pinut_device %s" % e)
TypeError: __str__ returned non-string (type InvalidName)
[06/Jul/2016 11:41:19] DEBUG [pinutcloud.views:52] Inside GET request
[06/Jul/2016 11:41:19] ERROR [django.request:284] Internal Server Error: /pinutcloud/getFeedbackRatings/
Traceback (most recent call last):
  File "/home/ec2-user/Virtual_Env/pinut_env/local/lib/python2.7/site-packages/django/core/handlers/base.py", line 149, in get_response
    response = self.process_exception_by_middleware(e, request)
  File "/home/ec2-user/Virtual_Env/pinut_env/local/lib/python2.7/site-packages/django/core/handlers/base.py", line 147, in get_response
    response = wrapped_callback(request, *callback_args, **callback_kwargs)
  File "/home/ec2-user/Virtual_Env/DjangoCloudCode/DjangoCloudCode/pinutcloud/views.py", line 59, in getFeedbackRatings
    feedback_ratings = utility_script_feedback.get_average_feedback(cust_name ,start_date_obj ,end_date_obj)
  File "/home/ec2-user/Virtual_Env/DjangoCloudCode/DjangoCloudCode/pinutcloud/analytics/utility_script_feedback.py", line 61, in get_average_feedback
    number_of_feedbacks = get_total_feedback(cust_name, start_date, end_date)
  File "/home/ec2-user/Virtual_Env/DjangoCloudCode/DjangoCloudCode/pinutcloud/analytics/utility_script_feedback.py", line 27, in get_total_feedback
    logging.exception("Exception, No feedback data %s" % e)
TypeError: __str__ returned non-string (type InvalidName)
[06/Jul/2016 11:41:19] DEBUG [pinutcloud.views:109] Inside GET request
[06/Jul/2016 11:41:19] ERROR [django.request:284] Internal Server Error: /pinutcloud/getUserIntroContent/
Traceback (most recent call last):
  File "/home/ec2-user/Virtual_Env/pinut_env/local/lib/python2.7/site-packages/django/core/handlers/base.py", line 149, in get_response
    response = self.process_exception_by_middleware(e, request)
  File "/home/ec2-user/Virtual_Env/pinut_env/local/lib/python2.7/site-packages/django/core/handlers/base.py", line 147, in get_response
    response = wrapped_callback(request, *callback_args, **callback_kwargs)
  File "/home/ec2-user/Virtual_Env/DjangoCloudCode/DjangoCloudCode/pinutcloud/views.py", line 116, in getUserIntroContent
    user_intro_content = utility_script_user_intro.get_user_intro_content(cust_name, start_date_obj, end_date_obj)
  File "/home/ec2-user/Virtual_Env/DjangoCloudCode/DjangoCloudCode/pinutcloud/analytics/utility_script_user_intro.py", line 47, in get_user_intro_content
    logging.exception("Exception, in processing user intro data %s" % e)
TypeError: __str__ returned non-string (type InvalidName)
[06/Jul/2016 11:41:19] DEBUG [pinutcloud.views:67] Inside GET request
[06/Jul/2016 11:41:19] ERROR [django.request:284] Internal Server Error: /pinutcloud/getFeedbackContent/
Traceback (most recent call last):
  File "/home/ec2-user/Virtual_Env/pinut_env/local/lib/python2.7/site-packages/django/core/handlers/base.py", line 149, in get_response
    response = self.process_exception_by_middleware(e, request)
  File "/home/ec2-user/Virtual_Env/pinut_env/local/lib/python2.7/site-packages/django/core/handlers/base.py", line 147, in get_response
    response = wrapped_callback(request, *callback_args, **callback_kwargs)
  File "/home/ec2-user/Virtual_Env/DjangoCloudCode/DjangoCloudCode/pinutcloud/views.py", line 74, in getFeedbackContent
    feedback_content = utility_script_feedback.get_feedback_content(cust_name ,start_date_obj ,end_date_obj)
  File "/home/ec2-user/Virtual_Env/DjangoCloudCode/DjangoCloudCode/pinutcloud/analytics/utility_script_feedback.py", line 33, in get_feedback_content
    number_of_feedbacks = get_total_feedback(cust_name, start_date, end_date)
  File "/home/ec2-user/Virtual_Env/DjangoCloudCode/DjangoCloudCode/pinutcloud/analytics/utility_script_feedback.py", line 27, in get_total_feedback
    logging.exception("Exception, No feedback data %s" % e)
TypeError: __str__ returned non-string (type InvalidName)
[06/Jul/2016 11:42:30] ERROR [django.request:284] Internal Server Error: /pinutcloud/getTotalDownloads/
Traceback (most recent call last):
  File "/home/ec2-user/Virtual_Env/pinut_env/local/lib/python2.7/site-packages/django/core/handlers/base.py", line 149, in get_response
    response = self.process_exception_by_middleware(e, request)
  File "/home/ec2-user/Virtual_Env/pinut_env/local/lib/python2.7/site-packages/django/core/handlers/base.py", line 147, in get_response
    response = wrapped_callback(request, *callback_args, **callback_kwargs)
  File "/home/ec2-user/Virtual_Env/DjangoCloudCode/DjangoCloudCode/pinutcloud/views.py", line 99, in getTotalDownloads
    number_of_downloads = utility_script_user_intro.get_number_of_downloads(cust_name ,start_date_obj ,end_date_obj)
  File "/home/ec2-user/Virtual_Env/DjangoCloudCode/DjangoCloudCode/pinutcloud/analytics/utility_script_user_intro.py", line 27, in get_number_of_downloads
    logging.exception("Exception, in getting number of downloads from user intro data %s" % e)
TypeError: __str__ returned non-string (type InvalidName)
[06/Jul/2016 11:42:31] DEBUG [pinutcloud.views:37] Inside GET request
[06/Jul/2016 11:42:31] ERROR [django.request:284] Internal Server Error: /pinutcloud/getTotalFeedback/
Traceback (most recent call last):
  File "/home/ec2-user/Virtual_Env/pinut_env/local/lib/python2.7/site-packages/django/core/handlers/base.py", line 149, in get_response
    response = self.process_exception_by_middleware(e, request)
  File "/home/ec2-user/Virtual_Env/pinut_env/local/lib/python2.7/site-packages/django/core/handlers/base.py", line 147, in get_response
    response = wrapped_callback(request, *callback_args, **callback_kwargs)
  File "/home/ec2-user/Virtual_Env/DjangoCloudCode/DjangoCloudCode/pinutcloud/views.py", line 44, in getTotalFeedback
    number_of_feedbacks = utility_script_feedback.get_total_feedback(cust_name ,start_date_obj ,end_date_obj)
  File "/home/ec2-user/Virtual_Env/DjangoCloudCode/DjangoCloudCode/pinutcloud/analytics/utility_script_feedback.py", line 27, in get_total_feedback
    logging.exception("Exception, No feedback data %s" % e)
TypeError: __str__ returned non-string (type InvalidName)
[06/Jul/2016 11:42:31] DEBUG [pinutcloud.views:130] Inside processmongodata
[06/Jul/2016 11:42:31] DEBUG [pinutcloud.views:132] Inside GET request
[06/Jul/2016 11:42:31] ERROR [django.request:284] Internal Server Error: /pinutcloud/processUserInfoMongoData/
Traceback (most recent call last):
  File "/home/ec2-user/Virtual_Env/pinut_env/local/lib/python2.7/site-packages/django/core/handlers/base.py", line 149, in get_response
    response = self.process_exception_by_middleware(e, request)
  File "/home/ec2-user/Virtual_Env/pinut_env/local/lib/python2.7/site-packages/django/core/handlers/base.py", line 147, in get_response
    response = wrapped_callback(request, *callback_args, **callback_kwargs)
  File "/home/ec2-user/Virtual_Env/DjangoCloudCode/DjangoCloudCode/pinutcloud/views.py", line 139, in processUserInfoMongoData
    user_info_data = utility_script_user_info.get_data_per_location(cust_name ,start_date_obj ,end_date_obj)
  File "/home/ec2-user/Virtual_Env/DjangoCloudCode/DjangoCloudCode/pinutcloud/analytics/utility_script_user_info.py", line 124, in get_data_per_location
    lid_devicemac_dict = get_data_per_device(cust_name ,start_date_obj ,end_date_obj)
  File "/home/ec2-user/Virtual_Env/DjangoCloudCode/DjangoCloudCode/pinutcloud/analytics/utility_script_user_info.py", line 112, in get_data_per_device
    logging.exception("Exception, in processing data across pinut_device %s" % e)
TypeError: __str__ returned non-string (type InvalidName)
[06/Jul/2016 11:42:31] DEBUG [pinutcloud.views:52] Inside GET request
[06/Jul/2016 11:42:31] ERROR [django.request:284] Internal Server Error: /pinutcloud/getFeedbackRatings/
Traceback (most recent call last):
  File "/home/ec2-user/Virtual_Env/pinut_env/local/lib/python2.7/site-packages/django/core/handlers/base.py", line 149, in get_response
    response = self.process_exception_by_middleware(e, request)
  File "/home/ec2-user/Virtual_Env/pinut_env/local/lib/python2.7/site-packages/django/core/handlers/base.py", line 147, in get_response
    response = wrapped_callback(request, *callback_args, **callback_kwargs)
  File "/home/ec2-user/Virtual_Env/DjangoCloudCode/DjangoCloudCode/pinutcloud/views.py", line 59, in getFeedbackRatings
    feedback_ratings = utility_script_feedback.get_average_feedback(cust_name ,start_date_obj ,end_date_obj)
  File "/home/ec2-user/Virtual_Env/DjangoCloudCode/DjangoCloudCode/pinutcloud/analytics/utility_script_feedback.py", line 61, in get_average_feedback
    number_of_feedbacks = get_total_feedback(cust_name, start_date, end_date)
  File "/home/ec2-user/Virtual_Env/DjangoCloudCode/DjangoCloudCode/pinutcloud/analytics/utility_script_feedback.py", line 27, in get_total_feedback
    logging.exception("Exception, No feedback data %s" % e)
TypeError: __str__ returned non-string (type InvalidName)
[06/Jul/2016 11:42:31] DEBUG [pinutcloud.views:109] Inside GET request
[06/Jul/2016 11:42:31] ERROR [django.request:284] Internal Server Error: /pinutcloud/getUserIntroContent/
Traceback (most recent call last):
  File "/home/ec2-user/Virtual_Env/pinut_env/local/lib/python2.7/site-packages/django/core/handlers/base.py", line 149, in get_response
    response = self.process_exception_by_middleware(e, request)
  File "/home/ec2-user/Virtual_Env/pinut_env/local/lib/python2.7/site-packages/django/core/handlers/base.py", line 147, in get_response
    response = wrapped_callback(request, *callback_args, **callback_kwargs)
  File "/home/ec2-user/Virtual_Env/DjangoCloudCode/DjangoCloudCode/pinutcloud/views.py", line 116, in getUserIntroContent
    user_intro_content = utility_script_user_intro.get_user_intro_content(cust_name, start_date_obj, end_date_obj)
  File "/home/ec2-user/Virtual_Env/DjangoCloudCode/DjangoCloudCode/pinutcloud/analytics/utility_script_user_intro.py", line 47, in get_user_intro_content
    logging.exception("Exception, in processing user intro data %s" % e)
TypeError: __str__ returned non-string (type InvalidName)
[06/Jul/2016 11:42:31] DEBUG [pinutcloud.views:67] Inside GET request
[06/Jul/2016 11:42:31] ERROR [django.request:284] Internal Server Error: /pinutcloud/getFeedbackContent/
Traceback (most recent call last):
  File "/home/ec2-user/Virtual_Env/pinut_env/local/lib/python2.7/site-packages/django/core/handlers/base.py", line 149, in get_response
    response = self.process_exception_by_middleware(e, request)
  File "/home/ec2-user/Virtual_Env/pinut_env/local/lib/python2.7/site-packages/django/core/handlers/base.py", line 147, in get_response
    response = wrapped_callback(request, *callback_args, **callback_kwargs)
  File "/home/ec2-user/Virtual_Env/DjangoCloudCode/DjangoCloudCode/pinutcloud/views.py", line 74, in getFeedbackContent
    feedback_content = utility_script_feedback.get_feedback_content(cust_name ,start_date_obj ,end_date_obj)
  File "/home/ec2-user/Virtual_Env/DjangoCloudCode/DjangoCloudCode/pinutcloud/analytics/utility_script_feedback.py", line 33, in get_feedback_content
    number_of_feedbacks = get_total_feedback(cust_name, start_date, end_date)
  File "/home/ec2-user/Virtual_Env/DjangoCloudCode/DjangoCloudCode/pinutcloud/analytics/utility_script_feedback.py", line 27, in get_total_feedback
    logging.exception("Exception, No feedback data %s" % e)
TypeError: __str__ returned non-string (type InvalidName)
[06/Jul/2016 12:34:46] ERROR [django.request:284] Internal Server Error: /pinutcloud/getTotalDownloads/
Traceback (most recent call last):
  File "/home/ec2-user/Virtual_Env/pinut_env/local/lib/python2.7/site-packages/django/core/handlers/base.py", line 149, in get_response
    response = self.process_exception_by_middleware(e, request)
  File "/home/ec2-user/Virtual_Env/pinut_env/local/lib/python2.7/site-packages/django/core/handlers/base.py", line 147, in get_response
    response = wrapped_callback(request, *callback_args, **callback_kwargs)
  File "/home/ec2-user/Virtual_Env/DjangoCloudCode/DjangoCloudCode/pinutcloud/views.py", line 99, in getTotalDownloads
    number_of_downloads = utility_script_user_intro.get_number_of_downloads(cust_name ,start_date_obj ,end_date_obj)
  File "/home/ec2-user/Virtual_Env/DjangoCloudCode/DjangoCloudCode/pinutcloud/analytics/utility_script_user_intro.py", line 27, in get_number_of_downloads
    logging.exception("Exception, in getting number of downloads from user intro data %s" % e)
TypeError: __str__ returned non-string (type InvalidName)
[06/Jul/2016 12:34:46] DEBUG [pinutcloud.views:37] Inside GET request
[06/Jul/2016 12:34:46] ERROR [django.request:284] Internal Server Error: /pinutcloud/getTotalFeedback/
Traceback (most recent call last):
  File "/home/ec2-user/Virtual_Env/pinut_env/local/lib/python2.7/site-packages/django/core/handlers/base.py", line 149, in get_response
    response = self.process_exception_by_middleware(e, request)
  File "/home/ec2-user/Virtual_Env/pinut_env/local/lib/python2.7/site-packages/django/core/handlers/base.py", line 147, in get_response
    response = wrapped_callback(request, *callback_args, **callback_kwargs)
  File "/home/ec2-user/Virtual_Env/DjangoCloudCode/DjangoCloudCode/pinutcloud/views.py", line 44, in getTotalFeedback
    number_of_feedbacks = utility_script_feedback.get_total_feedback(cust_name ,start_date_obj ,end_date_obj)
  File "/home/ec2-user/Virtual_Env/DjangoCloudCode/DjangoCloudCode/pinutcloud/analytics/utility_script_feedback.py", line 27, in get_total_feedback
    logging.exception("Exception, No feedback data %s" % e)
TypeError: __str__ returned non-string (type InvalidName)
[06/Jul/2016 12:34:46] DEBUG [pinutcloud.views:130] Inside processmongodata
[06/Jul/2016 12:34:46] DEBUG [pinutcloud.views:132] Inside GET request
[06/Jul/2016 12:34:46] ERROR [django.request:284] Internal Server Error: /pinutcloud/processUserInfoMongoData/
Traceback (most recent call last):
  File "/home/ec2-user/Virtual_Env/pinut_env/local/lib/python2.7/site-packages/django/core/handlers/base.py", line 149, in get_response
    response = self.process_exception_by_middleware(e, request)
  File "/home/ec2-user/Virtual_Env/pinut_env/local/lib/python2.7/site-packages/django/core/handlers/base.py", line 147, in get_response
    response = wrapped_callback(request, *callback_args, **callback_kwargs)
  File "/home/ec2-user/Virtual_Env/DjangoCloudCode/DjangoCloudCode/pinutcloud/views.py", line 139, in processUserInfoMongoData
    user_info_data = utility_script_user_info.get_data_per_location(cust_name ,start_date_obj ,end_date_obj)
  File "/home/ec2-user/Virtual_Env/DjangoCloudCode/DjangoCloudCode/pinutcloud/analytics/utility_script_user_info.py", line 124, in get_data_per_location
    lid_devicemac_dict = get_data_per_device(cust_name ,start_date_obj ,end_date_obj)
  File "/home/ec2-user/Virtual_Env/DjangoCloudCode/DjangoCloudCode/pinutcloud/analytics/utility_script_user_info.py", line 112, in get_data_per_device
    logging.exception("Exception, in processing data across pinut_device %s" % e)
TypeError: __str__ returned non-string (type InvalidName)
[06/Jul/2016 12:34:47] DEBUG [pinutcloud.views:52] Inside GET request
[06/Jul/2016 12:34:47] ERROR [django.request:284] Internal Server Error: /pinutcloud/getFeedbackRatings/
Traceback (most recent call last):
  File "/home/ec2-user/Virtual_Env/pinut_env/local/lib/python2.7/site-packages/django/core/handlers/base.py", line 149, in get_response
    response = self.process_exception_by_middleware(e, request)
  File "/home/ec2-user/Virtual_Env/pinut_env/local/lib/python2.7/site-packages/django/core/handlers/base.py", line 147, in get_response
    response = wrapped_callback(request, *callback_args, **callback_kwargs)
  File "/home/ec2-user/Virtual_Env/DjangoCloudCode/DjangoCloudCode/pinutcloud/views.py", line 59, in getFeedbackRatings
    feedback_ratings = utility_script_feedback.get_average_feedback(cust_name ,start_date_obj ,end_date_obj)
  File "/home/ec2-user/Virtual_Env/DjangoCloudCode/DjangoCloudCode/pinutcloud/analytics/utility_script_feedback.py", line 61, in get_average_feedback
    number_of_feedbacks = get_total_feedback(cust_name, start_date, end_date)
  File "/home/ec2-user/Virtual_Env/DjangoCloudCode/DjangoCloudCode/pinutcloud/analytics/utility_script_feedback.py", line 27, in get_total_feedback
    logging.exception("Exception, No feedback data %s" % e)
TypeError: __str__ returned non-string (type InvalidName)
[06/Jul/2016 12:34:47] DEBUG [pinutcloud.views:109] Inside GET request
[06/Jul/2016 12:34:47] ERROR [django.request:284] Internal Server Error: /pinutcloud/getUserIntroContent/
Traceback (most recent call last):
  File "/home/ec2-user/Virtual_Env/pinut_env/local/lib/python2.7/site-packages/django/core/handlers/base.py", line 149, in get_response
    response = self.process_exception_by_middleware(e, request)
  File "/home/ec2-user/Virtual_Env/pinut_env/local/lib/python2.7/site-packages/django/core/handlers/base.py", line 147, in get_response
    response = wrapped_callback(request, *callback_args, **callback_kwargs)
  File "/home/ec2-user/Virtual_Env/DjangoCloudCode/DjangoCloudCode/pinutcloud/views.py", line 116, in getUserIntroContent
    user_intro_content = utility_script_user_intro.get_user_intro_content(cust_name, start_date_obj, end_date_obj)
  File "/home/ec2-user/Virtual_Env/DjangoCloudCode/DjangoCloudCode/pinutcloud/analytics/utility_script_user_intro.py", line 47, in get_user_intro_content
    logging.exception("Exception, in processing user intro data %s" % e)
TypeError: __str__ returned non-string (type InvalidName)
[06/Jul/2016 12:34:47] DEBUG [pinutcloud.views:67] Inside GET request
[06/Jul/2016 12:34:47] ERROR [django.request:284] Internal Server Error: /pinutcloud/getFeedbackContent/
Traceback (most recent call last):
  File "/home/ec2-user/Virtual_Env/pinut_env/local/lib/python2.7/site-packages/django/core/handlers/base.py", line 149, in get_response
    response = self.process_exception_by_middleware(e, request)
  File "/home/ec2-user/Virtual_Env/pinut_env/local/lib/python2.7/site-packages/django/core/handlers/base.py", line 147, in get_response
    response = wrapped_callback(request, *callback_args, **callback_kwargs)
  File "/home/ec2-user/Virtual_Env/DjangoCloudCode/DjangoCloudCode/pinutcloud/views.py", line 74, in getFeedbackContent
    feedback_content = utility_script_feedback.get_feedback_content(cust_name ,start_date_obj ,end_date_obj)
  File "/home/ec2-user/Virtual_Env/DjangoCloudCode/DjangoCloudCode/pinutcloud/analytics/utility_script_feedback.py", line 33, in get_feedback_content
    number_of_feedbacks = get_total_feedback(cust_name, start_date, end_date)
  File "/home/ec2-user/Virtual_Env/DjangoCloudCode/DjangoCloudCode/pinutcloud/analytics/utility_script_feedback.py", line 27, in get_total_feedback
    logging.exception("Exception, No feedback data %s" % e)
TypeError: __str__ returned non-string (type InvalidName)
[06/Jul/2016 13:31:05] ERROR [django.request:284] Internal Server Error: /pinutcloud/getTotalDownloads/
Traceback (most recent call last):
  File "/home/ec2-user/Virtual_Env/pinut_env/local/lib/python2.7/site-packages/django/core/handlers/base.py", line 149, in get_response
    response = self.process_exception_by_middleware(e, request)
  File "/home/ec2-user/Virtual_Env/pinut_env/local/lib/python2.7/site-packages/django/core/handlers/base.py", line 147, in get_response
    response = wrapped_callback(request, *callback_args, **callback_kwargs)
  File "/home/ec2-user/Virtual_Env/DjangoCloudCode/DjangoCloudCode/pinutcloud/views.py", line 99, in getTotalDownloads
    number_of_downloads = utility_script_user_intro.get_number_of_downloads(cust_name ,start_date_obj ,end_date_obj)
  File "/home/ec2-user/Virtual_Env/DjangoCloudCode/DjangoCloudCode/pinutcloud/analytics/utility_script_user_intro.py", line 27, in get_number_of_downloads
    logging.exception("Exception, in getting number of downloads from user intro data %s" % e)
TypeError: __str__ returned non-string (type InvalidName)
[06/Jul/2016 13:31:06] DEBUG [pinutcloud.views:37] Inside GET request
[06/Jul/2016 13:31:06] ERROR [django.request:284] Internal Server Error: /pinutcloud/getTotalFeedback/
Traceback (most recent call last):
  File "/home/ec2-user/Virtual_Env/pinut_env/local/lib/python2.7/site-packages/django/core/handlers/base.py", line 149, in get_response
    response = self.process_exception_by_middleware(e, request)
  File "/home/ec2-user/Virtual_Env/pinut_env/local/lib/python2.7/site-packages/django/core/handlers/base.py", line 147, in get_response
    response = wrapped_callback(request, *callback_args, **callback_kwargs)
  File "/home/ec2-user/Virtual_Env/DjangoCloudCode/DjangoCloudCode/pinutcloud/views.py", line 44, in getTotalFeedback
    number_of_feedbacks = utility_script_feedback.get_total_feedback(cust_name ,start_date_obj ,end_date_obj)
  File "/home/ec2-user/Virtual_Env/DjangoCloudCode/DjangoCloudCode/pinutcloud/analytics/utility_script_feedback.py", line 27, in get_total_feedback
    logging.exception("Exception, No feedback data %s" % e)
TypeError: __str__ returned non-string (type InvalidName)
[06/Jul/2016 13:31:06] DEBUG [pinutcloud.views:130] Inside processmongodata
[06/Jul/2016 13:31:06] DEBUG [pinutcloud.views:132] Inside GET request
[06/Jul/2016 13:31:06] ERROR [django.request:284] Internal Server Error: /pinutcloud/processUserInfoMongoData/
Traceback (most recent call last):
  File "/home/ec2-user/Virtual_Env/pinut_env/local/lib/python2.7/site-packages/django/core/handlers/base.py", line 149, in get_response
    response = self.process_exception_by_middleware(e, request)
  File "/home/ec2-user/Virtual_Env/pinut_env/local/lib/python2.7/site-packages/django/core/handlers/base.py", line 147, in get_response
    response = wrapped_callback(request, *callback_args, **callback_kwargs)
  File "/home/ec2-user/Virtual_Env/DjangoCloudCode/DjangoCloudCode/pinutcloud/views.py", line 139, in processUserInfoMongoData
    user_info_data = utility_script_user_info.get_data_per_location(cust_name ,start_date_obj ,end_date_obj)
  File "/home/ec2-user/Virtual_Env/DjangoCloudCode/DjangoCloudCode/pinutcloud/analytics/utility_script_user_info.py", line 124, in get_data_per_location
    lid_devicemac_dict = get_data_per_device(cust_name ,start_date_obj ,end_date_obj)
  File "/home/ec2-user/Virtual_Env/DjangoCloudCode/DjangoCloudCode/pinutcloud/analytics/utility_script_user_info.py", line 112, in get_data_per_device
    logging.exception("Exception, in processing data across pinut_device %s" % e)
TypeError: __str__ returned non-string (type InvalidName)
[06/Jul/2016 13:31:06] DEBUG [pinutcloud.views:52] Inside GET request
[06/Jul/2016 13:31:06] ERROR [django.request:284] Internal Server Error: /pinutcloud/getFeedbackRatings/
Traceback (most recent call last):
  File "/home/ec2-user/Virtual_Env/pinut_env/local/lib/python2.7/site-packages/django/core/handlers/base.py", line 149, in get_response
    response = self.process_exception_by_middleware(e, request)
  File "/home/ec2-user/Virtual_Env/pinut_env/local/lib/python2.7/site-packages/django/core/handlers/base.py", line 147, in get_response
    response = wrapped_callback(request, *callback_args, **callback_kwargs)
  File "/home/ec2-user/Virtual_Env/DjangoCloudCode/DjangoCloudCode/pinutcloud/views.py", line 59, in getFeedbackRatings
    feedback_ratings = utility_script_feedback.get_average_feedback(cust_name ,start_date_obj ,end_date_obj)
  File "/home/ec2-user/Virtual_Env/DjangoCloudCode/DjangoCloudCode/pinutcloud/analytics/utility_script_feedback.py", line 61, in get_average_feedback
    number_of_feedbacks = get_total_feedback(cust_name, start_date, end_date)
  File "/home/ec2-user/Virtual_Env/DjangoCloudCode/DjangoCloudCode/pinutcloud/analytics/utility_script_feedback.py", line 27, in get_total_feedback
    logging.exception("Exception, No feedback data %s" % e)
TypeError: __str__ returned non-string (type InvalidName)
[06/Jul/2016 13:31:06] DEBUG [pinutcloud.views:109] Inside GET request
[06/Jul/2016 13:31:06] ERROR [django.request:284] Internal Server Error: /pinutcloud/getUserIntroContent/
Traceback (most recent call last):
  File "/home/ec2-user/Virtual_Env/pinut_env/local/lib/python2.7/site-packages/django/core/handlers/base.py", line 149, in get_response
    response = self.process_exception_by_middleware(e, request)
  File "/home/ec2-user/Virtual_Env/pinut_env/local/lib/python2.7/site-packages/django/core/handlers/base.py", line 147, in get_response
    response = wrapped_callback(request, *callback_args, **callback_kwargs)
  File "/home/ec2-user/Virtual_Env/DjangoCloudCode/DjangoCloudCode/pinutcloud/views.py", line 116, in getUserIntroContent
    user_intro_content = utility_script_user_intro.get_user_intro_content(cust_name, start_date_obj, end_date_obj)
  File "/home/ec2-user/Virtual_Env/DjangoCloudCode/DjangoCloudCode/pinutcloud/analytics/utility_script_user_intro.py", line 47, in get_user_intro_content
    logging.exception("Exception, in processing user intro data %s" % e)
TypeError: __str__ returned non-string (type InvalidName)
[06/Jul/2016 13:31:07] DEBUG [pinutcloud.views:67] Inside GET request
[06/Jul/2016 13:31:07] ERROR [django.request:284] Internal Server Error: /pinutcloud/getFeedbackContent/
Traceback (most recent call last):
  File "/home/ec2-user/Virtual_Env/pinut_env/local/lib/python2.7/site-packages/django/core/handlers/base.py", line 149, in get_response
    response = self.process_exception_by_middleware(e, request)
  File "/home/ec2-user/Virtual_Env/pinut_env/local/lib/python2.7/site-packages/django/core/handlers/base.py", line 147, in get_response
    response = wrapped_callback(request, *callback_args, **callback_kwargs)
  File "/home/ec2-user/Virtual_Env/DjangoCloudCode/DjangoCloudCode/pinutcloud/views.py", line 74, in getFeedbackContent
    feedback_content = utility_script_feedback.get_feedback_content(cust_name ,start_date_obj ,end_date_obj)
  File "/home/ec2-user/Virtual_Env/DjangoCloudCode/DjangoCloudCode/pinutcloud/analytics/utility_script_feedback.py", line 33, in get_feedback_content
    number_of_feedbacks = get_total_feedback(cust_name, start_date, end_date)
  File "/home/ec2-user/Virtual_Env/DjangoCloudCode/DjangoCloudCode/pinutcloud/analytics/utility_script_feedback.py", line 27, in get_total_feedback
    logging.exception("Exception, No feedback data %s" % e)
TypeError: __str__ returned non-string (type InvalidName)
[06/Jul/2016 13:32:29] ERROR [django.request:284] Internal Server Error: /pinutcloud/getTotalDownloads/
Traceback (most recent call last):
  File "/home/ec2-user/Virtual_Env/pinut_env/local/lib/python2.7/site-packages/django/core/handlers/base.py", line 149, in get_response
    response = self.process_exception_by_middleware(e, request)
  File "/home/ec2-user/Virtual_Env/pinut_env/local/lib/python2.7/site-packages/django/core/handlers/base.py", line 147, in get_response
    response = wrapped_callback(request, *callback_args, **callback_kwargs)
  File "/home/ec2-user/Virtual_Env/DjangoCloudCode/DjangoCloudCode/pinutcloud/views.py", line 99, in getTotalDownloads
    number_of_downloads = utility_script_user_intro.get_number_of_downloads(cust_name ,start_date_obj ,end_date_obj)
  File "/home/ec2-user/Virtual_Env/DjangoCloudCode/DjangoCloudCode/pinutcloud/analytics/utility_script_user_intro.py", line 27, in get_number_of_downloads
    logging.exception("Exception, in getting number of downloads from user intro data %s" % e)
TypeError: __str__ returned non-string (type InvalidName)
[06/Jul/2016 13:32:29] DEBUG [pinutcloud.views:37] Inside GET request
[06/Jul/2016 13:32:29] ERROR [django.request:284] Internal Server Error: /pinutcloud/getTotalFeedback/
Traceback (most recent call last):
  File "/home/ec2-user/Virtual_Env/pinut_env/local/lib/python2.7/site-packages/django/core/handlers/base.py", line 149, in get_response
    response = self.process_exception_by_middleware(e, request)
  File "/home/ec2-user/Virtual_Env/pinut_env/local/lib/python2.7/site-packages/django/core/handlers/base.py", line 147, in get_response
    response = wrapped_callback(request, *callback_args, **callback_kwargs)
  File "/home/ec2-user/Virtual_Env/DjangoCloudCode/DjangoCloudCode/pinutcloud/views.py", line 44, in getTotalFeedback
    number_of_feedbacks = utility_script_feedback.get_total_feedback(cust_name ,start_date_obj ,end_date_obj)
  File "/home/ec2-user/Virtual_Env/DjangoCloudCode/DjangoCloudCode/pinutcloud/analytics/utility_script_feedback.py", line 27, in get_total_feedback
    logging.exception("Exception, No feedback data %s" % e)
TypeError: __str__ returned non-string (type InvalidName)
[06/Jul/2016 13:32:29] DEBUG [pinutcloud.views:130] Inside processmongodata
[06/Jul/2016 13:32:29] DEBUG [pinutcloud.views:132] Inside GET request
[06/Jul/2016 13:32:29] ERROR [django.request:284] Internal Server Error: /pinutcloud/processUserInfoMongoData/
Traceback (most recent call last):
  File "/home/ec2-user/Virtual_Env/pinut_env/local/lib/python2.7/site-packages/django/core/handlers/base.py", line 149, in get_response
    response = self.process_exception_by_middleware(e, request)
  File "/home/ec2-user/Virtual_Env/pinut_env/local/lib/python2.7/site-packages/django/core/handlers/base.py", line 147, in get_response
    response = wrapped_callback(request, *callback_args, **callback_kwargs)
  File "/home/ec2-user/Virtual_Env/DjangoCloudCode/DjangoCloudCode/pinutcloud/views.py", line 139, in processUserInfoMongoData
    user_info_data = utility_script_user_info.get_data_per_location(cust_name ,start_date_obj ,end_date_obj)
  File "/home/ec2-user/Virtual_Env/DjangoCloudCode/DjangoCloudCode/pinutcloud/analytics/utility_script_user_info.py", line 124, in get_data_per_location
    lid_devicemac_dict = get_data_per_device(cust_name ,start_date_obj ,end_date_obj)
  File "/home/ec2-user/Virtual_Env/DjangoCloudCode/DjangoCloudCode/pinutcloud/analytics/utility_script_user_info.py", line 112, in get_data_per_device
    logging.exception("Exception, in processing data across pinut_device %s" % e)
TypeError: __str__ returned non-string (type InvalidName)
[06/Jul/2016 13:32:30] DEBUG [pinutcloud.views:52] Inside GET request
[06/Jul/2016 13:32:30] ERROR [django.request:284] Internal Server Error: /pinutcloud/getFeedbackRatings/
Traceback (most recent call last):
  File "/home/ec2-user/Virtual_Env/pinut_env/local/lib/python2.7/site-packages/django/core/handlers/base.py", line 149, in get_response
    response = self.process_exception_by_middleware(e, request)
  File "/home/ec2-user/Virtual_Env/pinut_env/local/lib/python2.7/site-packages/django/core/handlers/base.py", line 147, in get_response
    response = wrapped_callback(request, *callback_args, **callback_kwargs)
  File "/home/ec2-user/Virtual_Env/DjangoCloudCode/DjangoCloudCode/pinutcloud/views.py", line 59, in getFeedbackRatings
    feedback_ratings = utility_script_feedback.get_average_feedback(cust_name ,start_date_obj ,end_date_obj)
  File "/home/ec2-user/Virtual_Env/DjangoCloudCode/DjangoCloudCode/pinutcloud/analytics/utility_script_feedback.py", line 61, in get_average_feedback
    number_of_feedbacks = get_total_feedback(cust_name, start_date, end_date)
  File "/home/ec2-user/Virtual_Env/DjangoCloudCode/DjangoCloudCode/pinutcloud/analytics/utility_script_feedback.py", line 27, in get_total_feedback
    logging.exception("Exception, No feedback data %s" % e)
TypeError: __str__ returned non-string (type InvalidName)
[06/Jul/2016 13:32:30] DEBUG [pinutcloud.views:109] Inside GET request
[06/Jul/2016 13:32:30] ERROR [django.request:284] Internal Server Error: /pinutcloud/getUserIntroContent/
Traceback (most recent call last):
  File "/home/ec2-user/Virtual_Env/pinut_env/local/lib/python2.7/site-packages/django/core/handlers/base.py", line 149, in get_response
    response = self.process_exception_by_middleware(e, request)
  File "/home/ec2-user/Virtual_Env/pinut_env/local/lib/python2.7/site-packages/django/core/handlers/base.py", line 147, in get_response
    response = wrapped_callback(request, *callback_args, **callback_kwargs)
  File "/home/ec2-user/Virtual_Env/DjangoCloudCode/DjangoCloudCode/pinutcloud/views.py", line 116, in getUserIntroContent
    user_intro_content = utility_script_user_intro.get_user_intro_content(cust_name, start_date_obj, end_date_obj)
  File "/home/ec2-user/Virtual_Env/DjangoCloudCode/DjangoCloudCode/pinutcloud/analytics/utility_script_user_intro.py", line 47, in get_user_intro_content
    logging.exception("Exception, in processing user intro data %s" % e)
TypeError: __str__ returned non-string (type InvalidName)
[06/Jul/2016 13:32:30] DEBUG [pinutcloud.views:67] Inside GET request
[06/Jul/2016 13:32:30] ERROR [django.request:284] Internal Server Error: /pinutcloud/getFeedbackContent/
Traceback (most recent call last):
  File "/home/ec2-user/Virtual_Env/pinut_env/local/lib/python2.7/site-packages/django/core/handlers/base.py", line 149, in get_response
    response = self.process_exception_by_middleware(e, request)
  File "/home/ec2-user/Virtual_Env/pinut_env/local/lib/python2.7/site-packages/django/core/handlers/base.py", line 147, in get_response
    response = wrapped_callback(request, *callback_args, **callback_kwargs)
  File "/home/ec2-user/Virtual_Env/DjangoCloudCode/DjangoCloudCode/pinutcloud/views.py", line 74, in getFeedbackContent
    feedback_content = utility_script_feedback.get_feedback_content(cust_name ,start_date_obj ,end_date_obj)
  File "/home/ec2-user/Virtual_Env/DjangoCloudCode/DjangoCloudCode/pinutcloud/analytics/utility_script_feedback.py", line 33, in get_feedback_content
    number_of_feedbacks = get_total_feedback(cust_name, start_date, end_date)
  File "/home/ec2-user/Virtual_Env/DjangoCloudCode/DjangoCloudCode/pinutcloud/analytics/utility_script_feedback.py", line 27, in get_total_feedback
    logging.exception("Exception, No feedback data %s" % e)
TypeError: __str__ returned non-string (type InvalidName)
[06/Jul/2016 13:36:07] ERROR [django.request:284] Internal Server Error: /pinutcloud/getTotalDownloads/
Traceback (most recent call last):
  File "/home/ec2-user/Virtual_Env/pinut_env/local/lib/python2.7/site-packages/django/core/handlers/base.py", line 149, in get_response
    response = self.process_exception_by_middleware(e, request)
  File "/home/ec2-user/Virtual_Env/pinut_env/local/lib/python2.7/site-packages/django/core/handlers/base.py", line 147, in get_response
    response = wrapped_callback(request, *callback_args, **callback_kwargs)
  File "/home/ec2-user/Virtual_Env/DjangoCloudCode/DjangoCloudCode/pinutcloud/views.py", line 99, in getTotalDownloads
    number_of_downloads = utility_script_user_intro.get_number_of_downloads(cust_name ,start_date_obj ,end_date_obj)
  File "/home/ec2-user/Virtual_Env/DjangoCloudCode/DjangoCloudCode/pinutcloud/analytics/utility_script_user_intro.py", line 27, in get_number_of_downloads
    logging.exception("Exception, in getting number of downloads from user intro data %s" % e)
TypeError: __str__ returned non-string (type InvalidName)
[06/Jul/2016 13:36:07] DEBUG [pinutcloud.views:37] Inside GET request
[06/Jul/2016 13:36:07] ERROR [django.request:284] Internal Server Error: /pinutcloud/getTotalFeedback/
Traceback (most recent call last):
  File "/home/ec2-user/Virtual_Env/pinut_env/local/lib/python2.7/site-packages/django/core/handlers/base.py", line 149, in get_response
    response = self.process_exception_by_middleware(e, request)
  File "/home/ec2-user/Virtual_Env/pinut_env/local/lib/python2.7/site-packages/django/core/handlers/base.py", line 147, in get_response
    response = wrapped_callback(request, *callback_args, **callback_kwargs)
  File "/home/ec2-user/Virtual_Env/DjangoCloudCode/DjangoCloudCode/pinutcloud/views.py", line 44, in getTotalFeedback
    number_of_feedbacks = utility_script_feedback.get_total_feedback(cust_name ,start_date_obj ,end_date_obj)
  File "/home/ec2-user/Virtual_Env/DjangoCloudCode/DjangoCloudCode/pinutcloud/analytics/utility_script_feedback.py", line 27, in get_total_feedback
    logging.exception("Exception, No feedback data %s" % e)
TypeError: __str__ returned non-string (type InvalidName)
[06/Jul/2016 13:36:07] DEBUG [pinutcloud.views:130] Inside processmongodata
[06/Jul/2016 13:36:07] DEBUG [pinutcloud.views:132] Inside GET request
[06/Jul/2016 13:36:07] ERROR [django.request:284] Internal Server Error: /pinutcloud/processUserInfoMongoData/
Traceback (most recent call last):
  File "/home/ec2-user/Virtual_Env/pinut_env/local/lib/python2.7/site-packages/django/core/handlers/base.py", line 149, in get_response
    response = self.process_exception_by_middleware(e, request)
  File "/home/ec2-user/Virtual_Env/pinut_env/local/lib/python2.7/site-packages/django/core/handlers/base.py", line 147, in get_response
    response = wrapped_callback(request, *callback_args, **callback_kwargs)
  File "/home/ec2-user/Virtual_Env/DjangoCloudCode/DjangoCloudCode/pinutcloud/views.py", line 139, in processUserInfoMongoData
    user_info_data = utility_script_user_info.get_data_per_location(cust_name ,start_date_obj ,end_date_obj)
  File "/home/ec2-user/Virtual_Env/DjangoCloudCode/DjangoCloudCode/pinutcloud/analytics/utility_script_user_info.py", line 124, in get_data_per_location
    lid_devicemac_dict = get_data_per_device(cust_name ,start_date_obj ,end_date_obj)
  File "/home/ec2-user/Virtual_Env/DjangoCloudCode/DjangoCloudCode/pinutcloud/analytics/utility_script_user_info.py", line 112, in get_data_per_device
    logging.exception("Exception, in processing data across pinut_device %s" % e)
TypeError: __str__ returned non-string (type InvalidName)
[06/Jul/2016 13:36:08] DEBUG [pinutcloud.views:52] Inside GET request
[06/Jul/2016 13:36:08] ERROR [django.request:284] Internal Server Error: /pinutcloud/getFeedbackRatings/
Traceback (most recent call last):
  File "/home/ec2-user/Virtual_Env/pinut_env/local/lib/python2.7/site-packages/django/core/handlers/base.py", line 149, in get_response
    response = self.process_exception_by_middleware(e, request)
  File "/home/ec2-user/Virtual_Env/pinut_env/local/lib/python2.7/site-packages/django/core/handlers/base.py", line 147, in get_response
    response = wrapped_callback(request, *callback_args, **callback_kwargs)
  File "/home/ec2-user/Virtual_Env/DjangoCloudCode/DjangoCloudCode/pinutcloud/views.py", line 59, in getFeedbackRatings
    feedback_ratings = utility_script_feedback.get_average_feedback(cust_name ,start_date_obj ,end_date_obj)
  File "/home/ec2-user/Virtual_Env/DjangoCloudCode/DjangoCloudCode/pinutcloud/analytics/utility_script_feedback.py", line 61, in get_average_feedback
    number_of_feedbacks = get_total_feedback(cust_name, start_date, end_date)
  File "/home/ec2-user/Virtual_Env/DjangoCloudCode/DjangoCloudCode/pinutcloud/analytics/utility_script_feedback.py", line 27, in get_total_feedback
    logging.exception("Exception, No feedback data %s" % e)
TypeError: __str__ returned non-string (type InvalidName)
[06/Jul/2016 13:36:08] DEBUG [pinutcloud.views:109] Inside GET request
[06/Jul/2016 13:36:08] ERROR [django.request:284] Internal Server Error: /pinutcloud/getUserIntroContent/
Traceback (most recent call last):
  File "/home/ec2-user/Virtual_Env/pinut_env/local/lib/python2.7/site-packages/django/core/handlers/base.py", line 149, in get_response
    response = self.process_exception_by_middleware(e, request)
  File "/home/ec2-user/Virtual_Env/pinut_env/local/lib/python2.7/site-packages/django/core/handlers/base.py", line 147, in get_response
    response = wrapped_callback(request, *callback_args, **callback_kwargs)
  File "/home/ec2-user/Virtual_Env/DjangoCloudCode/DjangoCloudCode/pinutcloud/views.py", line 116, in getUserIntroContent
    user_intro_content = utility_script_user_intro.get_user_intro_content(cust_name, start_date_obj, end_date_obj)
  File "/home/ec2-user/Virtual_Env/DjangoCloudCode/DjangoCloudCode/pinutcloud/analytics/utility_script_user_intro.py", line 47, in get_user_intro_content
    logging.exception("Exception, in processing user intro data %s" % e)
TypeError: __str__ returned non-string (type InvalidName)
[06/Jul/2016 13:36:08] DEBUG [pinutcloud.views:67] Inside GET request
[06/Jul/2016 13:36:08] ERROR [django.request:284] Internal Server Error: /pinutcloud/getFeedbackContent/
Traceback (most recent call last):
  File "/home/ec2-user/Virtual_Env/pinut_env/local/lib/python2.7/site-packages/django/core/handlers/base.py", line 149, in get_response
    response = self.process_exception_by_middleware(e, request)
  File "/home/ec2-user/Virtual_Env/pinut_env/local/lib/python2.7/site-packages/django/core/handlers/base.py", line 147, in get_response
    response = wrapped_callback(request, *callback_args, **callback_kwargs)
  File "/home/ec2-user/Virtual_Env/DjangoCloudCode/DjangoCloudCode/pinutcloud/views.py", line 74, in getFeedbackContent
    feedback_content = utility_script_feedback.get_feedback_content(cust_name ,start_date_obj ,end_date_obj)
  File "/home/ec2-user/Virtual_Env/DjangoCloudCode/DjangoCloudCode/pinutcloud/analytics/utility_script_feedback.py", line 33, in get_feedback_content
    number_of_feedbacks = get_total_feedback(cust_name, start_date, end_date)
  File "/home/ec2-user/Virtual_Env/DjangoCloudCode/DjangoCloudCode/pinutcloud/analytics/utility_script_feedback.py", line 27, in get_total_feedback
    logging.exception("Exception, No feedback data %s" % e)
TypeError: __str__ returned non-string (type InvalidName)
[06/Jul/2016 13:36:28] ERROR [django.request:284] Internal Server Error: /pinutcloud/getTotalDownloads/
Traceback (most recent call last):
  File "/home/ec2-user/Virtual_Env/pinut_env/local/lib/python2.7/site-packages/django/core/handlers/base.py", line 149, in get_response
    response = self.process_exception_by_middleware(e, request)
  File "/home/ec2-user/Virtual_Env/pinut_env/local/lib/python2.7/site-packages/django/core/handlers/base.py", line 147, in get_response
    response = wrapped_callback(request, *callback_args, **callback_kwargs)
  File "/home/ec2-user/Virtual_Env/DjangoCloudCode/DjangoCloudCode/pinutcloud/views.py", line 99, in getTotalDownloads
    number_of_downloads = utility_script_user_intro.get_number_of_downloads(cust_name ,start_date_obj ,end_date_obj)
  File "/home/ec2-user/Virtual_Env/DjangoCloudCode/DjangoCloudCode/pinutcloud/analytics/utility_script_user_intro.py", line 27, in get_number_of_downloads
    logging.exception("Exception, in getting number of downloads from user intro data %s" % e)
TypeError: __str__ returned non-string (type InvalidName)
[06/Jul/2016 13:36:28] DEBUG [pinutcloud.views:37] Inside GET request
[06/Jul/2016 13:36:28] ERROR [django.request:284] Internal Server Error: /pinutcloud/getTotalFeedback/
Traceback (most recent call last):
  File "/home/ec2-user/Virtual_Env/pinut_env/local/lib/python2.7/site-packages/django/core/handlers/base.py", line 149, in get_response
    response = self.process_exception_by_middleware(e, request)
  File "/home/ec2-user/Virtual_Env/pinut_env/local/lib/python2.7/site-packages/django/core/handlers/base.py", line 147, in get_response
    response = wrapped_callback(request, *callback_args, **callback_kwargs)
  File "/home/ec2-user/Virtual_Env/DjangoCloudCode/DjangoCloudCode/pinutcloud/views.py", line 44, in getTotalFeedback
    number_of_feedbacks = utility_script_feedback.get_total_feedback(cust_name ,start_date_obj ,end_date_obj)
  File "/home/ec2-user/Virtual_Env/DjangoCloudCode/DjangoCloudCode/pinutcloud/analytics/utility_script_feedback.py", line 27, in get_total_feedback
    logging.exception("Exception, No feedback data %s" % e)
TypeError: __str__ returned non-string (type InvalidName)
[06/Jul/2016 13:36:28] DEBUG [pinutcloud.views:130] Inside processmongodata
[06/Jul/2016 13:36:28] DEBUG [pinutcloud.views:132] Inside GET request
[06/Jul/2016 13:36:28] ERROR [django.request:284] Internal Server Error: /pinutcloud/processUserInfoMongoData/
Traceback (most recent call last):
  File "/home/ec2-user/Virtual_Env/pinut_env/local/lib/python2.7/site-packages/django/core/handlers/base.py", line 149, in get_response
    response = self.process_exception_by_middleware(e, request)
  File "/home/ec2-user/Virtual_Env/pinut_env/local/lib/python2.7/site-packages/django/core/handlers/base.py", line 147, in get_response
    response = wrapped_callback(request, *callback_args, **callback_kwargs)
  File "/home/ec2-user/Virtual_Env/DjangoCloudCode/DjangoCloudCode/pinutcloud/views.py", line 139, in processUserInfoMongoData
    user_info_data = utility_script_user_info.get_data_per_location(cust_name ,start_date_obj ,end_date_obj)
  File "/home/ec2-user/Virtual_Env/DjangoCloudCode/DjangoCloudCode/pinutcloud/analytics/utility_script_user_info.py", line 124, in get_data_per_location
    lid_devicemac_dict = get_data_per_device(cust_name ,start_date_obj ,end_date_obj)
  File "/home/ec2-user/Virtual_Env/DjangoCloudCode/DjangoCloudCode/pinutcloud/analytics/utility_script_user_info.py", line 112, in get_data_per_device
    logging.exception("Exception, in processing data across pinut_device %s" % e)
TypeError: __str__ returned non-string (type InvalidName)
[06/Jul/2016 13:36:29] DEBUG [pinutcloud.views:52] Inside GET request
[06/Jul/2016 13:36:29] ERROR [django.request:284] Internal Server Error: /pinutcloud/getFeedbackRatings/
Traceback (most recent call last):
  File "/home/ec2-user/Virtual_Env/pinut_env/local/lib/python2.7/site-packages/django/core/handlers/base.py", line 149, in get_response
    response = self.process_exception_by_middleware(e, request)
  File "/home/ec2-user/Virtual_Env/pinut_env/local/lib/python2.7/site-packages/django/core/handlers/base.py", line 147, in get_response
    response = wrapped_callback(request, *callback_args, **callback_kwargs)
  File "/home/ec2-user/Virtual_Env/DjangoCloudCode/DjangoCloudCode/pinutcloud/views.py", line 59, in getFeedbackRatings
    feedback_ratings = utility_script_feedback.get_average_feedback(cust_name ,start_date_obj ,end_date_obj)
  File "/home/ec2-user/Virtual_Env/DjangoCloudCode/DjangoCloudCode/pinutcloud/analytics/utility_script_feedback.py", line 61, in get_average_feedback
    number_of_feedbacks = get_total_feedback(cust_name, start_date, end_date)
  File "/home/ec2-user/Virtual_Env/DjangoCloudCode/DjangoCloudCode/pinutcloud/analytics/utility_script_feedback.py", line 27, in get_total_feedback
    logging.exception("Exception, No feedback data %s" % e)
TypeError: __str__ returned non-string (type InvalidName)
[06/Jul/2016 13:36:29] DEBUG [pinutcloud.views:109] Inside GET request
[06/Jul/2016 13:36:29] ERROR [django.request:284] Internal Server Error: /pinutcloud/getUserIntroContent/
Traceback (most recent call last):
  File "/home/ec2-user/Virtual_Env/pinut_env/local/lib/python2.7/site-packages/django/core/handlers/base.py", line 149, in get_response
    response = self.process_exception_by_middleware(e, request)
  File "/home/ec2-user/Virtual_Env/pinut_env/local/lib/python2.7/site-packages/django/core/handlers/base.py", line 147, in get_response
    response = wrapped_callback(request, *callback_args, **callback_kwargs)
  File "/home/ec2-user/Virtual_Env/DjangoCloudCode/DjangoCloudCode/pinutcloud/views.py", line 116, in getUserIntroContent
    user_intro_content = utility_script_user_intro.get_user_intro_content(cust_name, start_date_obj, end_date_obj)
  File "/home/ec2-user/Virtual_Env/DjangoCloudCode/DjangoCloudCode/pinutcloud/analytics/utility_script_user_intro.py", line 47, in get_user_intro_content
    logging.exception("Exception, in processing user intro data %s" % e)
TypeError: __str__ returned non-string (type InvalidName)
[06/Jul/2016 13:36:29] DEBUG [pinutcloud.views:67] Inside GET request
[06/Jul/2016 13:36:29] ERROR [django.request:284] Internal Server Error: /pinutcloud/getFeedbackContent/
Traceback (most recent call last):
  File "/home/ec2-user/Virtual_Env/pinut_env/local/lib/python2.7/site-packages/django/core/handlers/base.py", line 149, in get_response
    response = self.process_exception_by_middleware(e, request)
  File "/home/ec2-user/Virtual_Env/pinut_env/local/lib/python2.7/site-packages/django/core/handlers/base.py", line 147, in get_response
    response = wrapped_callback(request, *callback_args, **callback_kwargs)
  File "/home/ec2-user/Virtual_Env/DjangoCloudCode/DjangoCloudCode/pinutcloud/views.py", line 74, in getFeedbackContent
    feedback_content = utility_script_feedback.get_feedback_content(cust_name ,start_date_obj ,end_date_obj)
  File "/home/ec2-user/Virtual_Env/DjangoCloudCode/DjangoCloudCode/pinutcloud/analytics/utility_script_feedback.py", line 33, in get_feedback_content
    number_of_feedbacks = get_total_feedback(cust_name, start_date, end_date)
  File "/home/ec2-user/Virtual_Env/DjangoCloudCode/DjangoCloudCode/pinutcloud/analytics/utility_script_feedback.py", line 27, in get_total_feedback
    logging.exception("Exception, No feedback data %s" % e)
TypeError: __str__ returned non-string (type InvalidName)
[06/Jul/2016 13:37:04] ERROR [django.request:284] Internal Server Error: /pinutcloud/getTotalDownloads/
Traceback (most recent call last):
  File "/home/ec2-user/Virtual_Env/pinut_env/local/lib/python2.7/site-packages/django/core/handlers/base.py", line 149, in get_response
    response = self.process_exception_by_middleware(e, request)
  File "/home/ec2-user/Virtual_Env/pinut_env/local/lib/python2.7/site-packages/django/core/handlers/base.py", line 147, in get_response
    response = wrapped_callback(request, *callback_args, **callback_kwargs)
  File "/home/ec2-user/Virtual_Env/DjangoCloudCode/DjangoCloudCode/pinutcloud/views.py", line 99, in getTotalDownloads
    number_of_downloads = utility_script_user_intro.get_number_of_downloads(cust_name ,start_date_obj ,end_date_obj)
  File "/home/ec2-user/Virtual_Env/DjangoCloudCode/DjangoCloudCode/pinutcloud/analytics/utility_script_user_intro.py", line 27, in get_number_of_downloads
    logging.exception("Exception, in getting number of downloads from user intro data %s" % e)
TypeError: __str__ returned non-string (type InvalidName)
[06/Jul/2016 13:37:05] DEBUG [pinutcloud.views:37] Inside GET request
[06/Jul/2016 13:37:05] ERROR [django.request:284] Internal Server Error: /pinutcloud/getTotalFeedback/
Traceback (most recent call last):
  File "/home/ec2-user/Virtual_Env/pinut_env/local/lib/python2.7/site-packages/django/core/handlers/base.py", line 149, in get_response
    response = self.process_exception_by_middleware(e, request)
  File "/home/ec2-user/Virtual_Env/pinut_env/local/lib/python2.7/site-packages/django/core/handlers/base.py", line 147, in get_response
    response = wrapped_callback(request, *callback_args, **callback_kwargs)
  File "/home/ec2-user/Virtual_Env/DjangoCloudCode/DjangoCloudCode/pinutcloud/views.py", line 44, in getTotalFeedback
    number_of_feedbacks = utility_script_feedback.get_total_feedback(cust_name ,start_date_obj ,end_date_obj)
  File "/home/ec2-user/Virtual_Env/DjangoCloudCode/DjangoCloudCode/pinutcloud/analytics/utility_script_feedback.py", line 27, in get_total_feedback
    logging.exception("Exception, No feedback data %s" % e)
TypeError: __str__ returned non-string (type InvalidName)
[06/Jul/2016 13:37:05] DEBUG [pinutcloud.views:130] Inside processmongodata
[06/Jul/2016 13:37:05] DEBUG [pinutcloud.views:132] Inside GET request
[06/Jul/2016 13:37:05] ERROR [django.request:284] Internal Server Error: /pinutcloud/processUserInfoMongoData/
Traceback (most recent call last):
  File "/home/ec2-user/Virtual_Env/pinut_env/local/lib/python2.7/site-packages/django/core/handlers/base.py", line 149, in get_response
    response = self.process_exception_by_middleware(e, request)
  File "/home/ec2-user/Virtual_Env/pinut_env/local/lib/python2.7/site-packages/django/core/handlers/base.py", line 147, in get_response
    response = wrapped_callback(request, *callback_args, **callback_kwargs)
  File "/home/ec2-user/Virtual_Env/DjangoCloudCode/DjangoCloudCode/pinutcloud/views.py", line 139, in processUserInfoMongoData
    user_info_data = utility_script_user_info.get_data_per_location(cust_name ,start_date_obj ,end_date_obj)
  File "/home/ec2-user/Virtual_Env/DjangoCloudCode/DjangoCloudCode/pinutcloud/analytics/utility_script_user_info.py", line 124, in get_data_per_location
    lid_devicemac_dict = get_data_per_device(cust_name ,start_date_obj ,end_date_obj)
  File "/home/ec2-user/Virtual_Env/DjangoCloudCode/DjangoCloudCode/pinutcloud/analytics/utility_script_user_info.py", line 112, in get_data_per_device
    logging.exception("Exception, in processing data across pinut_device %s" % e)
TypeError: __str__ returned non-string (type InvalidName)
[06/Jul/2016 13:37:05] DEBUG [pinutcloud.views:52] Inside GET request
[06/Jul/2016 13:37:05] ERROR [django.request:284] Internal Server Error: /pinutcloud/getFeedbackRatings/
Traceback (most recent call last):
  File "/home/ec2-user/Virtual_Env/pinut_env/local/lib/python2.7/site-packages/django/core/handlers/base.py", line 149, in get_response
    response = self.process_exception_by_middleware(e, request)
  File "/home/ec2-user/Virtual_Env/pinut_env/local/lib/python2.7/site-packages/django/core/handlers/base.py", line 147, in get_response
    response = wrapped_callback(request, *callback_args, **callback_kwargs)
  File "/home/ec2-user/Virtual_Env/DjangoCloudCode/DjangoCloudCode/pinutcloud/views.py", line 59, in getFeedbackRatings
    feedback_ratings = utility_script_feedback.get_average_feedback(cust_name ,start_date_obj ,end_date_obj)
  File "/home/ec2-user/Virtual_Env/DjangoCloudCode/DjangoCloudCode/pinutcloud/analytics/utility_script_feedback.py", line 61, in get_average_feedback
    number_of_feedbacks = get_total_feedback(cust_name, start_date, end_date)
  File "/home/ec2-user/Virtual_Env/DjangoCloudCode/DjangoCloudCode/pinutcloud/analytics/utility_script_feedback.py", line 27, in get_total_feedback
    logging.exception("Exception, No feedback data %s" % e)
TypeError: __str__ returned non-string (type InvalidName)
[06/Jul/2016 13:37:06] DEBUG [pinutcloud.views:109] Inside GET request
[06/Jul/2016 13:37:06] ERROR [django.request:284] Internal Server Error: /pinutcloud/getUserIntroContent/
Traceback (most recent call last):
  File "/home/ec2-user/Virtual_Env/pinut_env/local/lib/python2.7/site-packages/django/core/handlers/base.py", line 149, in get_response
    response = self.process_exception_by_middleware(e, request)
  File "/home/ec2-user/Virtual_Env/pinut_env/local/lib/python2.7/site-packages/django/core/handlers/base.py", line 147, in get_response
    response = wrapped_callback(request, *callback_args, **callback_kwargs)
  File "/home/ec2-user/Virtual_Env/DjangoCloudCode/DjangoCloudCode/pinutcloud/views.py", line 116, in getUserIntroContent
    user_intro_content = utility_script_user_intro.get_user_intro_content(cust_name, start_date_obj, end_date_obj)
  File "/home/ec2-user/Virtual_Env/DjangoCloudCode/DjangoCloudCode/pinutcloud/analytics/utility_script_user_intro.py", line 47, in get_user_intro_content
    logging.exception("Exception, in processing user intro data %s" % e)
TypeError: __str__ returned non-string (type InvalidName)
[06/Jul/2016 13:37:06] DEBUG [pinutcloud.views:67] Inside GET request
[06/Jul/2016 13:37:06] ERROR [django.request:284] Internal Server Error: /pinutcloud/getFeedbackContent/
Traceback (most recent call last):
  File "/home/ec2-user/Virtual_Env/pinut_env/local/lib/python2.7/site-packages/django/core/handlers/base.py", line 149, in get_response
    response = self.process_exception_by_middleware(e, request)
  File "/home/ec2-user/Virtual_Env/pinut_env/local/lib/python2.7/site-packages/django/core/handlers/base.py", line 147, in get_response
    response = wrapped_callback(request, *callback_args, **callback_kwargs)
  File "/home/ec2-user/Virtual_Env/DjangoCloudCode/DjangoCloudCode/pinutcloud/views.py", line 74, in getFeedbackContent
    feedback_content = utility_script_feedback.get_feedback_content(cust_name ,start_date_obj ,end_date_obj)
  File "/home/ec2-user/Virtual_Env/DjangoCloudCode/DjangoCloudCode/pinutcloud/analytics/utility_script_feedback.py", line 33, in get_feedback_content
    number_of_feedbacks = get_total_feedback(cust_name, start_date, end_date)
  File "/home/ec2-user/Virtual_Env/DjangoCloudCode/DjangoCloudCode/pinutcloud/analytics/utility_script_feedback.py", line 27, in get_total_feedback
    logging.exception("Exception, No feedback data %s" % e)
TypeError: __str__ returned non-string (type InvalidName)
[06/Jul/2016 13:38:17] ERROR [django.request:284] Internal Server Error: /pinutcloud/getTotalDownloads/
Traceback (most recent call last):
  File "/home/ec2-user/Virtual_Env/pinut_env/local/lib/python2.7/site-packages/django/core/handlers/base.py", line 149, in get_response
    response = self.process_exception_by_middleware(e, request)
  File "/home/ec2-user/Virtual_Env/pinut_env/local/lib/python2.7/site-packages/django/core/handlers/base.py", line 147, in get_response
    response = wrapped_callback(request, *callback_args, **callback_kwargs)
  File "/home/ec2-user/Virtual_Env/DjangoCloudCode/DjangoCloudCode/pinutcloud/views.py", line 87, in getTotalDownloads
    cust_name=request.GET['cust_name']
  File "/home/ec2-user/Virtual_Env/pinut_env/local/lib/python2.7/site-packages/django/utils/datastructures.py", line 85, in __getitem__
    raise MultiValueDictKeyError(repr(key))
MultiValueDictKeyError: "'cust_name'"
[06/Jul/2016 13:38:17] DEBUG [pinutcloud.views:37] Inside GET request
[06/Jul/2016 13:38:17] ERROR [django.request:284] Internal Server Error: /pinutcloud/getTotalFeedback/
Traceback (most recent call last):
  File "/home/ec2-user/Virtual_Env/pinut_env/local/lib/python2.7/site-packages/django/core/handlers/base.py", line 149, in get_response
    response = self.process_exception_by_middleware(e, request)
  File "/home/ec2-user/Virtual_Env/pinut_env/local/lib/python2.7/site-packages/django/core/handlers/base.py", line 147, in get_response
    response = wrapped_callback(request, *callback_args, **callback_kwargs)
  File "/home/ec2-user/Virtual_Env/DjangoCloudCode/DjangoCloudCode/pinutcloud/views.py", line 38, in getTotalFeedback
    cust_name=request.GET['cust_name']
  File "/home/ec2-user/Virtual_Env/pinut_env/local/lib/python2.7/site-packages/django/utils/datastructures.py", line 85, in __getitem__
    raise MultiValueDictKeyError(repr(key))
MultiValueDictKeyError: "'cust_name'"
[06/Jul/2016 13:38:18] DEBUG [pinutcloud.views:130] Inside processmongodata
[06/Jul/2016 13:38:18] DEBUG [pinutcloud.views:132] Inside GET request
[06/Jul/2016 13:38:18] ERROR [django.request:284] Internal Server Error: /pinutcloud/processUserInfoMongoData/
Traceback (most recent call last):
  File "/home/ec2-user/Virtual_Env/pinut_env/local/lib/python2.7/site-packages/django/core/handlers/base.py", line 149, in get_response
    response = self.process_exception_by_middleware(e, request)
  File "/home/ec2-user/Virtual_Env/pinut_env/local/lib/python2.7/site-packages/django/core/handlers/base.py", line 147, in get_response
    response = wrapped_callback(request, *callback_args, **callback_kwargs)
  File "/home/ec2-user/Virtual_Env/DjangoCloudCode/DjangoCloudCode/pinutcloud/views.py", line 133, in processUserInfoMongoData
    cust_name=request.GET['cust_name']
  File "/home/ec2-user/Virtual_Env/pinut_env/local/lib/python2.7/site-packages/django/utils/datastructures.py", line 85, in __getitem__
    raise MultiValueDictKeyError(repr(key))
MultiValueDictKeyError: "'cust_name'"
[06/Jul/2016 13:38:18] DEBUG [pinutcloud.views:52] Inside GET request
[06/Jul/2016 13:38:18] ERROR [django.request:284] Internal Server Error: /pinutcloud/getFeedbackRatings/
Traceback (most recent call last):
  File "/home/ec2-user/Virtual_Env/pinut_env/local/lib/python2.7/site-packages/django/core/handlers/base.py", line 149, in get_response
    response = self.process_exception_by_middleware(e, request)
  File "/home/ec2-user/Virtual_Env/pinut_env/local/lib/python2.7/site-packages/django/core/handlers/base.py", line 147, in get_response
    response = wrapped_callback(request, *callback_args, **callback_kwargs)
  File "/home/ec2-user/Virtual_Env/DjangoCloudCode/DjangoCloudCode/pinutcloud/views.py", line 53, in getFeedbackRatings
    cust_name=request.GET['cust_name']
  File "/home/ec2-user/Virtual_Env/pinut_env/local/lib/python2.7/site-packages/django/utils/datastructures.py", line 85, in __getitem__
    raise MultiValueDictKeyError(repr(key))
MultiValueDictKeyError: "'cust_name'"
[06/Jul/2016 13:38:18] DEBUG [pinutcloud.views:109] Inside GET request
[06/Jul/2016 13:38:18] ERROR [django.request:284] Internal Server Error: /pinutcloud/getUserIntroContent/
Traceback (most recent call last):
  File "/home/ec2-user/Virtual_Env/pinut_env/local/lib/python2.7/site-packages/django/core/handlers/base.py", line 149, in get_response
    response = self.process_exception_by_middleware(e, request)
  File "/home/ec2-user/Virtual_Env/pinut_env/local/lib/python2.7/site-packages/django/core/handlers/base.py", line 147, in get_response
    response = wrapped_callback(request, *callback_args, **callback_kwargs)
  File "/home/ec2-user/Virtual_Env/DjangoCloudCode/DjangoCloudCode/pinutcloud/views.py", line 110, in getUserIntroContent
    cust_name=request.GET['cust_name']
  File "/home/ec2-user/Virtual_Env/pinut_env/local/lib/python2.7/site-packages/django/utils/datastructures.py", line 85, in __getitem__
    raise MultiValueDictKeyError(repr(key))
MultiValueDictKeyError: "'cust_name'"
[06/Jul/2016 13:38:19] DEBUG [pinutcloud.views:67] Inside GET request
[06/Jul/2016 13:38:19] ERROR [django.request:284] Internal Server Error: /pinutcloud/getFeedbackContent/
Traceback (most recent call last):
  File "/home/ec2-user/Virtual_Env/pinut_env/local/lib/python2.7/site-packages/django/core/handlers/base.py", line 149, in get_response
    response = self.process_exception_by_middleware(e, request)
  File "/home/ec2-user/Virtual_Env/pinut_env/local/lib/python2.7/site-packages/django/core/handlers/base.py", line 147, in get_response
    response = wrapped_callback(request, *callback_args, **callback_kwargs)
  File "/home/ec2-user/Virtual_Env/DjangoCloudCode/DjangoCloudCode/pinutcloud/views.py", line 68, in getFeedbackContent
    cust_name=request.GET['cust_name']
  File "/home/ec2-user/Virtual_Env/pinut_env/local/lib/python2.7/site-packages/django/utils/datastructures.py", line 85, in __getitem__
    raise MultiValueDictKeyError(repr(key))
MultiValueDictKeyError: "'cust_name'"
[06/Jul/2016 13:38:28] ERROR [django.request:284] Internal Server Error: /pinutcloud/getTotalDownloads/
Traceback (most recent call last):
  File "/home/ec2-user/Virtual_Env/pinut_env/local/lib/python2.7/site-packages/django/core/handlers/base.py", line 149, in get_response
    response = self.process_exception_by_middleware(e, request)
  File "/home/ec2-user/Virtual_Env/pinut_env/local/lib/python2.7/site-packages/django/core/handlers/base.py", line 147, in get_response
    response = wrapped_callback(request, *callback_args, **callback_kwargs)
  File "/home/ec2-user/Virtual_Env/DjangoCloudCode/DjangoCloudCode/pinutcloud/views.py", line 87, in getTotalDownloads
    cust_name=request.GET['cust_name']
  File "/home/ec2-user/Virtual_Env/pinut_env/local/lib/python2.7/site-packages/django/utils/datastructures.py", line 85, in __getitem__
    raise MultiValueDictKeyError(repr(key))
MultiValueDictKeyError: "'cust_name'"
[06/Jul/2016 13:38:28] DEBUG [pinutcloud.views:37] Inside GET request
[06/Jul/2016 13:38:28] ERROR [django.request:284] Internal Server Error: /pinutcloud/getTotalFeedback/
Traceback (most recent call last):
  File "/home/ec2-user/Virtual_Env/pinut_env/local/lib/python2.7/site-packages/django/core/handlers/base.py", line 149, in get_response
    response = self.process_exception_by_middleware(e, request)
  File "/home/ec2-user/Virtual_Env/pinut_env/local/lib/python2.7/site-packages/django/core/handlers/base.py", line 147, in get_response
    response = wrapped_callback(request, *callback_args, **callback_kwargs)
  File "/home/ec2-user/Virtual_Env/DjangoCloudCode/DjangoCloudCode/pinutcloud/views.py", line 38, in getTotalFeedback
    cust_name=request.GET['cust_name']
  File "/home/ec2-user/Virtual_Env/pinut_env/local/lib/python2.7/site-packages/django/utils/datastructures.py", line 85, in __getitem__
    raise MultiValueDictKeyError(repr(key))
MultiValueDictKeyError: "'cust_name'"
[06/Jul/2016 13:38:28] DEBUG [pinutcloud.views:130] Inside processmongodata
[06/Jul/2016 13:38:28] DEBUG [pinutcloud.views:132] Inside GET request
[06/Jul/2016 13:38:28] ERROR [django.request:284] Internal Server Error: /pinutcloud/processUserInfoMongoData/
Traceback (most recent call last):
  File "/home/ec2-user/Virtual_Env/pinut_env/local/lib/python2.7/site-packages/django/core/handlers/base.py", line 149, in get_response
    response = self.process_exception_by_middleware(e, request)
  File "/home/ec2-user/Virtual_Env/pinut_env/local/lib/python2.7/site-packages/django/core/handlers/base.py", line 147, in get_response
    response = wrapped_callback(request, *callback_args, **callback_kwargs)
  File "/home/ec2-user/Virtual_Env/DjangoCloudCode/DjangoCloudCode/pinutcloud/views.py", line 133, in processUserInfoMongoData
    cust_name=request.GET['cust_name']
  File "/home/ec2-user/Virtual_Env/pinut_env/local/lib/python2.7/site-packages/django/utils/datastructures.py", line 85, in __getitem__
    raise MultiValueDictKeyError(repr(key))
MultiValueDictKeyError: "'cust_name'"
[06/Jul/2016 13:38:29] DEBUG [pinutcloud.views:52] Inside GET request
[06/Jul/2016 13:38:29] ERROR [django.request:284] Internal Server Error: /pinutcloud/getFeedbackRatings/
Traceback (most recent call last):
  File "/home/ec2-user/Virtual_Env/pinut_env/local/lib/python2.7/site-packages/django/core/handlers/base.py", line 149, in get_response
    response = self.process_exception_by_middleware(e, request)
  File "/home/ec2-user/Virtual_Env/pinut_env/local/lib/python2.7/site-packages/django/core/handlers/base.py", line 147, in get_response
    response = wrapped_callback(request, *callback_args, **callback_kwargs)
  File "/home/ec2-user/Virtual_Env/DjangoCloudCode/DjangoCloudCode/pinutcloud/views.py", line 53, in getFeedbackRatings
    cust_name=request.GET['cust_name']
  File "/home/ec2-user/Virtual_Env/pinut_env/local/lib/python2.7/site-packages/django/utils/datastructures.py", line 85, in __getitem__
    raise MultiValueDictKeyError(repr(key))
MultiValueDictKeyError: "'cust_name'"
[06/Jul/2016 13:38:29] DEBUG [pinutcloud.views:109] Inside GET request
[06/Jul/2016 13:38:29] ERROR [django.request:284] Internal Server Error: /pinutcloud/getUserIntroContent/
Traceback (most recent call last):
  File "/home/ec2-user/Virtual_Env/pinut_env/local/lib/python2.7/site-packages/django/core/handlers/base.py", line 149, in get_response
    response = self.process_exception_by_middleware(e, request)
  File "/home/ec2-user/Virtual_Env/pinut_env/local/lib/python2.7/site-packages/django/core/handlers/base.py", line 147, in get_response
    response = wrapped_callback(request, *callback_args, **callback_kwargs)
  File "/home/ec2-user/Virtual_Env/DjangoCloudCode/DjangoCloudCode/pinutcloud/views.py", line 110, in getUserIntroContent
    cust_name=request.GET['cust_name']
  File "/home/ec2-user/Virtual_Env/pinut_env/local/lib/python2.7/site-packages/django/utils/datastructures.py", line 85, in __getitem__
    raise MultiValueDictKeyError(repr(key))
MultiValueDictKeyError: "'cust_name'"
[06/Jul/2016 13:38:29] DEBUG [pinutcloud.views:67] Inside GET request
[06/Jul/2016 13:38:29] ERROR [django.request:284] Internal Server Error: /pinutcloud/getFeedbackContent/
Traceback (most recent call last):
  File "/home/ec2-user/Virtual_Env/pinut_env/local/lib/python2.7/site-packages/django/core/handlers/base.py", line 149, in get_response
    response = self.process_exception_by_middleware(e, request)
  File "/home/ec2-user/Virtual_Env/pinut_env/local/lib/python2.7/site-packages/django/core/handlers/base.py", line 147, in get_response
    response = wrapped_callback(request, *callback_args, **callback_kwargs)
  File "/home/ec2-user/Virtual_Env/DjangoCloudCode/DjangoCloudCode/pinutcloud/views.py", line 68, in getFeedbackContent
    cust_name=request.GET['cust_name']
  File "/home/ec2-user/Virtual_Env/pinut_env/local/lib/python2.7/site-packages/django/utils/datastructures.py", line 85, in __getitem__
    raise MultiValueDictKeyError(repr(key))
MultiValueDictKeyError: "'cust_name'"
[06/Jul/2016 13:39:13] ERROR [django.request:284] Internal Server Error: /pinutcloud/getTotalDownloads/
Traceback (most recent call last):
  File "/home/ec2-user/Virtual_Env/pinut_env/local/lib/python2.7/site-packages/django/core/handlers/base.py", line 149, in get_response
    response = self.process_exception_by_middleware(e, request)
  File "/home/ec2-user/Virtual_Env/pinut_env/local/lib/python2.7/site-packages/django/core/handlers/base.py", line 147, in get_response
    response = wrapped_callback(request, *callback_args, **callback_kwargs)
  File "/home/ec2-user/Virtual_Env/DjangoCloudCode/DjangoCloudCode/pinutcloud/views.py", line 99, in getTotalDownloads
    number_of_downloads = utility_script_user_intro.get_number_of_downloads(cust_name ,start_date_obj ,end_date_obj)
  File "/home/ec2-user/Virtual_Env/DjangoCloudCode/DjangoCloudCode/pinutcloud/analytics/utility_script_user_intro.py", line 27, in get_number_of_downloads
    logging.exception("Exception, in getting number of downloads from user intro data %s" % e)
TypeError: __str__ returned non-string (type InvalidName)
[06/Jul/2016 13:39:13] DEBUG [pinutcloud.views:37] Inside GET request
[06/Jul/2016 13:39:13] ERROR [django.request:284] Internal Server Error: /pinutcloud/getTotalFeedback/
Traceback (most recent call last):
  File "/home/ec2-user/Virtual_Env/pinut_env/local/lib/python2.7/site-packages/django/core/handlers/base.py", line 149, in get_response
    response = self.process_exception_by_middleware(e, request)
  File "/home/ec2-user/Virtual_Env/pinut_env/local/lib/python2.7/site-packages/django/core/handlers/base.py", line 147, in get_response
    response = wrapped_callback(request, *callback_args, **callback_kwargs)
  File "/home/ec2-user/Virtual_Env/DjangoCloudCode/DjangoCloudCode/pinutcloud/views.py", line 44, in getTotalFeedback
    number_of_feedbacks = utility_script_feedback.get_total_feedback(cust_name ,start_date_obj ,end_date_obj)
  File "/home/ec2-user/Virtual_Env/DjangoCloudCode/DjangoCloudCode/pinutcloud/analytics/utility_script_feedback.py", line 27, in get_total_feedback
    logging.exception("Exception, No feedback data %s" % e)
TypeError: __str__ returned non-string (type InvalidName)
[06/Jul/2016 13:39:14] DEBUG [pinutcloud.views:130] Inside processmongodata
[06/Jul/2016 13:39:14] DEBUG [pinutcloud.views:132] Inside GET request
[06/Jul/2016 13:39:14] ERROR [django.request:284] Internal Server Error: /pinutcloud/processUserInfoMongoData/
Traceback (most recent call last):
  File "/home/ec2-user/Virtual_Env/pinut_env/local/lib/python2.7/site-packages/django/core/handlers/base.py", line 149, in get_response
    response = self.process_exception_by_middleware(e, request)
  File "/home/ec2-user/Virtual_Env/pinut_env/local/lib/python2.7/site-packages/django/core/handlers/base.py", line 147, in get_response
    response = wrapped_callback(request, *callback_args, **callback_kwargs)
  File "/home/ec2-user/Virtual_Env/DjangoCloudCode/DjangoCloudCode/pinutcloud/views.py", line 139, in processUserInfoMongoData
    user_info_data = utility_script_user_info.get_data_per_location(cust_name ,start_date_obj ,end_date_obj)
  File "/home/ec2-user/Virtual_Env/DjangoCloudCode/DjangoCloudCode/pinutcloud/analytics/utility_script_user_info.py", line 124, in get_data_per_location
    lid_devicemac_dict = get_data_per_device(cust_name ,start_date_obj ,end_date_obj)
  File "/home/ec2-user/Virtual_Env/DjangoCloudCode/DjangoCloudCode/pinutcloud/analytics/utility_script_user_info.py", line 112, in get_data_per_device
    logging.exception("Exception, in processing data across pinut_device %s" % e)
TypeError: __str__ returned non-string (type InvalidName)
[06/Jul/2016 13:39:14] DEBUG [pinutcloud.views:52] Inside GET request
[06/Jul/2016 13:39:14] ERROR [django.request:284] Internal Server Error: /pinutcloud/getFeedbackRatings/
Traceback (most recent call last):
  File "/home/ec2-user/Virtual_Env/pinut_env/local/lib/python2.7/site-packages/django/core/handlers/base.py", line 149, in get_response
    response = self.process_exception_by_middleware(e, request)
  File "/home/ec2-user/Virtual_Env/pinut_env/local/lib/python2.7/site-packages/django/core/handlers/base.py", line 147, in get_response
    response = wrapped_callback(request, *callback_args, **callback_kwargs)
  File "/home/ec2-user/Virtual_Env/DjangoCloudCode/DjangoCloudCode/pinutcloud/views.py", line 59, in getFeedbackRatings
    feedback_ratings = utility_script_feedback.get_average_feedback(cust_name ,start_date_obj ,end_date_obj)
  File "/home/ec2-user/Virtual_Env/DjangoCloudCode/DjangoCloudCode/pinutcloud/analytics/utility_script_feedback.py", line 61, in get_average_feedback
    number_of_feedbacks = get_total_feedback(cust_name, start_date, end_date)
  File "/home/ec2-user/Virtual_Env/DjangoCloudCode/DjangoCloudCode/pinutcloud/analytics/utility_script_feedback.py", line 27, in get_total_feedback
    logging.exception("Exception, No feedback data %s" % e)
TypeError: __str__ returned non-string (type InvalidName)
[06/Jul/2016 13:39:14] DEBUG [pinutcloud.views:109] Inside GET request
[06/Jul/2016 13:39:14] ERROR [django.request:284] Internal Server Error: /pinutcloud/getUserIntroContent/
Traceback (most recent call last):
  File "/home/ec2-user/Virtual_Env/pinut_env/local/lib/python2.7/site-packages/django/core/handlers/base.py", line 149, in get_response
    response = self.process_exception_by_middleware(e, request)
  File "/home/ec2-user/Virtual_Env/pinut_env/local/lib/python2.7/site-packages/django/core/handlers/base.py", line 147, in get_response
    response = wrapped_callback(request, *callback_args, **callback_kwargs)
  File "/home/ec2-user/Virtual_Env/DjangoCloudCode/DjangoCloudCode/pinutcloud/views.py", line 116, in getUserIntroContent
    user_intro_content = utility_script_user_intro.get_user_intro_content(cust_name, start_date_obj, end_date_obj)
  File "/home/ec2-user/Virtual_Env/DjangoCloudCode/DjangoCloudCode/pinutcloud/analytics/utility_script_user_intro.py", line 47, in get_user_intro_content
    logging.exception("Exception, in processing user intro data %s" % e)
TypeError: __str__ returned non-string (type InvalidName)
[06/Jul/2016 13:39:15] DEBUG [pinutcloud.views:67] Inside GET request
[06/Jul/2016 13:39:15] ERROR [django.request:284] Internal Server Error: /pinutcloud/getFeedbackContent/
Traceback (most recent call last):
  File "/home/ec2-user/Virtual_Env/pinut_env/local/lib/python2.7/site-packages/django/core/handlers/base.py", line 149, in get_response
    response = self.process_exception_by_middleware(e, request)
  File "/home/ec2-user/Virtual_Env/pinut_env/local/lib/python2.7/site-packages/django/core/handlers/base.py", line 147, in get_response
    response = wrapped_callback(request, *callback_args, **callback_kwargs)
  File "/home/ec2-user/Virtual_Env/DjangoCloudCode/DjangoCloudCode/pinutcloud/views.py", line 74, in getFeedbackContent
    feedback_content = utility_script_feedback.get_feedback_content(cust_name ,start_date_obj ,end_date_obj)
  File "/home/ec2-user/Virtual_Env/DjangoCloudCode/DjangoCloudCode/pinutcloud/analytics/utility_script_feedback.py", line 33, in get_feedback_content
    number_of_feedbacks = get_total_feedback(cust_name, start_date, end_date)
  File "/home/ec2-user/Virtual_Env/DjangoCloudCode/DjangoCloudCode/pinutcloud/analytics/utility_script_feedback.py", line 27, in get_total_feedback
    logging.exception("Exception, No feedback data %s" % e)
TypeError: __str__ returned non-string (type InvalidName)
[06/Jul/2016 14:25:20] ERROR [django.request:284] Internal Server Error: /pinutcloud/getTotalDownloads/
Traceback (most recent call last):
  File "/home/ec2-user/Virtual_Env/pinut_env/local/lib/python2.7/site-packages/django/core/handlers/base.py", line 149, in get_response
    response = self.process_exception_by_middleware(e, request)
  File "/home/ec2-user/Virtual_Env/pinut_env/local/lib/python2.7/site-packages/django/core/handlers/base.py", line 147, in get_response
    response = wrapped_callback(request, *callback_args, **callback_kwargs)
  File "/home/ec2-user/Virtual_Env/DjangoCloudCode/DjangoCloudCode/pinutcloud/views.py", line 87, in getTotalDownloads
    cust_name=request.GET['cust_name']
  File "/home/ec2-user/Virtual_Env/pinut_env/local/lib/python2.7/site-packages/django/utils/datastructures.py", line 85, in __getitem__
    raise MultiValueDictKeyError(repr(key))
MultiValueDictKeyError: "'cust_name'"
[06/Jul/2016 14:25:21] DEBUG [pinutcloud.views:37] Inside GET request
[06/Jul/2016 14:25:21] ERROR [django.request:284] Internal Server Error: /pinutcloud/getTotalFeedback/
Traceback (most recent call last):
  File "/home/ec2-user/Virtual_Env/pinut_env/local/lib/python2.7/site-packages/django/core/handlers/base.py", line 149, in get_response
    response = self.process_exception_by_middleware(e, request)
  File "/home/ec2-user/Virtual_Env/pinut_env/local/lib/python2.7/site-packages/django/core/handlers/base.py", line 147, in get_response
    response = wrapped_callback(request, *callback_args, **callback_kwargs)
  File "/home/ec2-user/Virtual_Env/DjangoCloudCode/DjangoCloudCode/pinutcloud/views.py", line 38, in getTotalFeedback
    cust_name=request.GET['cust_name']
  File "/home/ec2-user/Virtual_Env/pinut_env/local/lib/python2.7/site-packages/django/utils/datastructures.py", line 85, in __getitem__
    raise MultiValueDictKeyError(repr(key))
MultiValueDictKeyError: "'cust_name'"
[06/Jul/2016 14:25:21] DEBUG [pinutcloud.views:130] Inside processmongodata
[06/Jul/2016 14:25:21] DEBUG [pinutcloud.views:132] Inside GET request
[06/Jul/2016 14:25:21] ERROR [django.request:284] Internal Server Error: /pinutcloud/processUserInfoMongoData/
Traceback (most recent call last):
  File "/home/ec2-user/Virtual_Env/pinut_env/local/lib/python2.7/site-packages/django/core/handlers/base.py", line 149, in get_response
    response = self.process_exception_by_middleware(e, request)
  File "/home/ec2-user/Virtual_Env/pinut_env/local/lib/python2.7/site-packages/django/core/handlers/base.py", line 147, in get_response
    response = wrapped_callback(request, *callback_args, **callback_kwargs)
  File "/home/ec2-user/Virtual_Env/DjangoCloudCode/DjangoCloudCode/pinutcloud/views.py", line 133, in processUserInfoMongoData
    cust_name=request.GET['cust_name']
  File "/home/ec2-user/Virtual_Env/pinut_env/local/lib/python2.7/site-packages/django/utils/datastructures.py", line 85, in __getitem__
    raise MultiValueDictKeyError(repr(key))
MultiValueDictKeyError: "'cust_name'"
[06/Jul/2016 14:25:22] DEBUG [pinutcloud.views:52] Inside GET request
[06/Jul/2016 14:25:22] ERROR [django.request:284] Internal Server Error: /pinutcloud/getFeedbackRatings/
Traceback (most recent call last):
  File "/home/ec2-user/Virtual_Env/pinut_env/local/lib/python2.7/site-packages/django/core/handlers/base.py", line 149, in get_response
    response = self.process_exception_by_middleware(e, request)
  File "/home/ec2-user/Virtual_Env/pinut_env/local/lib/python2.7/site-packages/django/core/handlers/base.py", line 147, in get_response
    response = wrapped_callback(request, *callback_args, **callback_kwargs)
  File "/home/ec2-user/Virtual_Env/DjangoCloudCode/DjangoCloudCode/pinutcloud/views.py", line 53, in getFeedbackRatings
    cust_name=request.GET['cust_name']
  File "/home/ec2-user/Virtual_Env/pinut_env/local/lib/python2.7/site-packages/django/utils/datastructures.py", line 85, in __getitem__
    raise MultiValueDictKeyError(repr(key))
MultiValueDictKeyError: "'cust_name'"
[06/Jul/2016 14:25:22] DEBUG [pinutcloud.views:109] Inside GET request
[06/Jul/2016 14:25:22] ERROR [django.request:284] Internal Server Error: /pinutcloud/getUserIntroContent/
Traceback (most recent call last):
  File "/home/ec2-user/Virtual_Env/pinut_env/local/lib/python2.7/site-packages/django/core/handlers/base.py", line 149, in get_response
    response = self.process_exception_by_middleware(e, request)
  File "/home/ec2-user/Virtual_Env/pinut_env/local/lib/python2.7/site-packages/django/core/handlers/base.py", line 147, in get_response
    response = wrapped_callback(request, *callback_args, **callback_kwargs)
  File "/home/ec2-user/Virtual_Env/DjangoCloudCode/DjangoCloudCode/pinutcloud/views.py", line 110, in getUserIntroContent
    cust_name=request.GET['cust_name']
  File "/home/ec2-user/Virtual_Env/pinut_env/local/lib/python2.7/site-packages/django/utils/datastructures.py", line 85, in __getitem__
    raise MultiValueDictKeyError(repr(key))
MultiValueDictKeyError: "'cust_name'"
[06/Jul/2016 14:25:22] DEBUG [pinutcloud.views:67] Inside GET request
[06/Jul/2016 14:25:22] ERROR [django.request:284] Internal Server Error: /pinutcloud/getFeedbackContent/
Traceback (most recent call last):
  File "/home/ec2-user/Virtual_Env/pinut_env/local/lib/python2.7/site-packages/django/core/handlers/base.py", line 149, in get_response
    response = self.process_exception_by_middleware(e, request)
  File "/home/ec2-user/Virtual_Env/pinut_env/local/lib/python2.7/site-packages/django/core/handlers/base.py", line 147, in get_response
    response = wrapped_callback(request, *callback_args, **callback_kwargs)
  File "/home/ec2-user/Virtual_Env/DjangoCloudCode/DjangoCloudCode/pinutcloud/views.py", line 68, in getFeedbackContent
    cust_name=request.GET['cust_name']
  File "/home/ec2-user/Virtual_Env/pinut_env/local/lib/python2.7/site-packages/django/utils/datastructures.py", line 85, in __getitem__
    raise MultiValueDictKeyError(repr(key))
MultiValueDictKeyError: "'cust_name'"
[06/Jul/2016 14:26:17] ERROR [django.request:284] Internal Server Error: /pinutcloud/getTotalDownloads/
Traceback (most recent call last):
  File "/home/ec2-user/Virtual_Env/pinut_env/local/lib/python2.7/site-packages/django/core/handlers/base.py", line 149, in get_response
    response = self.process_exception_by_middleware(e, request)
  File "/home/ec2-user/Virtual_Env/pinut_env/local/lib/python2.7/site-packages/django/core/handlers/base.py", line 147, in get_response
    response = wrapped_callback(request, *callback_args, **callback_kwargs)
  File "/home/ec2-user/Virtual_Env/DjangoCloudCode/DjangoCloudCode/pinutcloud/views.py", line 87, in getTotalDownloads
    cust_name=request.GET['cust_name']
  File "/home/ec2-user/Virtual_Env/pinut_env/local/lib/python2.7/site-packages/django/utils/datastructures.py", line 85, in __getitem__
    raise MultiValueDictKeyError(repr(key))
MultiValueDictKeyError: "'cust_name'"
[06/Jul/2016 14:26:18] DEBUG [pinutcloud.views:37] Inside GET request
[06/Jul/2016 14:26:18] ERROR [django.request:284] Internal Server Error: /pinutcloud/getTotalFeedback/
Traceback (most recent call last):
  File "/home/ec2-user/Virtual_Env/pinut_env/local/lib/python2.7/site-packages/django/core/handlers/base.py", line 149, in get_response
    response = self.process_exception_by_middleware(e, request)
  File "/home/ec2-user/Virtual_Env/pinut_env/local/lib/python2.7/site-packages/django/core/handlers/base.py", line 147, in get_response
    response = wrapped_callback(request, *callback_args, **callback_kwargs)
  File "/home/ec2-user/Virtual_Env/DjangoCloudCode/DjangoCloudCode/pinutcloud/views.py", line 38, in getTotalFeedback
    cust_name=request.GET['cust_name']
  File "/home/ec2-user/Virtual_Env/pinut_env/local/lib/python2.7/site-packages/django/utils/datastructures.py", line 85, in __getitem__
    raise MultiValueDictKeyError(repr(key))
MultiValueDictKeyError: "'cust_name'"
[06/Jul/2016 14:26:18] DEBUG [pinutcloud.views:130] Inside processmongodata
[06/Jul/2016 14:26:18] DEBUG [pinutcloud.views:132] Inside GET request
[06/Jul/2016 14:26:18] ERROR [django.request:284] Internal Server Error: /pinutcloud/processUserInfoMongoData/
Traceback (most recent call last):
  File "/home/ec2-user/Virtual_Env/pinut_env/local/lib/python2.7/site-packages/django/core/handlers/base.py", line 149, in get_response
    response = self.process_exception_by_middleware(e, request)
  File "/home/ec2-user/Virtual_Env/pinut_env/local/lib/python2.7/site-packages/django/core/handlers/base.py", line 147, in get_response
    response = wrapped_callback(request, *callback_args, **callback_kwargs)
  File "/home/ec2-user/Virtual_Env/DjangoCloudCode/DjangoCloudCode/pinutcloud/views.py", line 133, in processUserInfoMongoData
    cust_name=request.GET['cust_name']
  File "/home/ec2-user/Virtual_Env/pinut_env/local/lib/python2.7/site-packages/django/utils/datastructures.py", line 85, in __getitem__
    raise MultiValueDictKeyError(repr(key))
MultiValueDictKeyError: "'cust_name'"
[06/Jul/2016 14:26:18] DEBUG [pinutcloud.views:52] Inside GET request
[06/Jul/2016 14:26:18] ERROR [django.request:284] Internal Server Error: /pinutcloud/getFeedbackRatings/
Traceback (most recent call last):
  File "/home/ec2-user/Virtual_Env/pinut_env/local/lib/python2.7/site-packages/django/core/handlers/base.py", line 149, in get_response
    response = self.process_exception_by_middleware(e, request)
  File "/home/ec2-user/Virtual_Env/pinut_env/local/lib/python2.7/site-packages/django/core/handlers/base.py", line 147, in get_response
    response = wrapped_callback(request, *callback_args, **callback_kwargs)
  File "/home/ec2-user/Virtual_Env/DjangoCloudCode/DjangoCloudCode/pinutcloud/views.py", line 53, in getFeedbackRatings
    cust_name=request.GET['cust_name']
  File "/home/ec2-user/Virtual_Env/pinut_env/local/lib/python2.7/site-packages/django/utils/datastructures.py", line 85, in __getitem__
    raise MultiValueDictKeyError(repr(key))
MultiValueDictKeyError: "'cust_name'"
[06/Jul/2016 14:26:19] DEBUG [pinutcloud.views:109] Inside GET request
[06/Jul/2016 14:26:19] ERROR [django.request:284] Internal Server Error: /pinutcloud/getUserIntroContent/
Traceback (most recent call last):
  File "/home/ec2-user/Virtual_Env/pinut_env/local/lib/python2.7/site-packages/django/core/handlers/base.py", line 149, in get_response
    response = self.process_exception_by_middleware(e, request)
  File "/home/ec2-user/Virtual_Env/pinut_env/local/lib/python2.7/site-packages/django/core/handlers/base.py", line 147, in get_response
    response = wrapped_callback(request, *callback_args, **callback_kwargs)
  File "/home/ec2-user/Virtual_Env/DjangoCloudCode/DjangoCloudCode/pinutcloud/views.py", line 110, in getUserIntroContent
    cust_name=request.GET['cust_name']
  File "/home/ec2-user/Virtual_Env/pinut_env/local/lib/python2.7/site-packages/django/utils/datastructures.py", line 85, in __getitem__
    raise MultiValueDictKeyError(repr(key))
MultiValueDictKeyError: "'cust_name'"
[06/Jul/2016 14:26:19] DEBUG [pinutcloud.views:67] Inside GET request
[06/Jul/2016 14:26:19] ERROR [django.request:284] Internal Server Error: /pinutcloud/getFeedbackContent/
Traceback (most recent call last):
  File "/home/ec2-user/Virtual_Env/pinut_env/local/lib/python2.7/site-packages/django/core/handlers/base.py", line 149, in get_response
    response = self.process_exception_by_middleware(e, request)
  File "/home/ec2-user/Virtual_Env/pinut_env/local/lib/python2.7/site-packages/django/core/handlers/base.py", line 147, in get_response
    response = wrapped_callback(request, *callback_args, **callback_kwargs)
  File "/home/ec2-user/Virtual_Env/DjangoCloudCode/DjangoCloudCode/pinutcloud/views.py", line 68, in getFeedbackContent
    cust_name=request.GET['cust_name']
  File "/home/ec2-user/Virtual_Env/pinut_env/local/lib/python2.7/site-packages/django/utils/datastructures.py", line 85, in __getitem__
    raise MultiValueDictKeyError(repr(key))
MultiValueDictKeyError: "'cust_name'"
[06/Jul/2016 14:28:02] ERROR [django.request:284] Internal Server Error: /pinutcloud/getTotalDownloads/
Traceback (most recent call last):
  File "/home/ec2-user/Virtual_Env/pinut_env/local/lib/python2.7/site-packages/django/core/handlers/base.py", line 149, in get_response
    response = self.process_exception_by_middleware(e, request)
  File "/home/ec2-user/Virtual_Env/pinut_env/local/lib/python2.7/site-packages/django/core/handlers/base.py", line 147, in get_response
    response = wrapped_callback(request, *callback_args, **callback_kwargs)
  File "/home/ec2-user/Virtual_Env/DjangoCloudCode/DjangoCloudCode/pinutcloud/views.py", line 87, in getTotalDownloads
    cust_name=request.GET['cust_name']
  File "/home/ec2-user/Virtual_Env/pinut_env/local/lib/python2.7/site-packages/django/utils/datastructures.py", line 85, in __getitem__
    raise MultiValueDictKeyError(repr(key))
MultiValueDictKeyError: "'cust_name'"
[06/Jul/2016 14:28:02] DEBUG [pinutcloud.views:37] Inside GET request
[06/Jul/2016 14:28:02] ERROR [django.request:284] Internal Server Error: /pinutcloud/getTotalFeedback/
Traceback (most recent call last):
  File "/home/ec2-user/Virtual_Env/pinut_env/local/lib/python2.7/site-packages/django/core/handlers/base.py", line 149, in get_response
    response = self.process_exception_by_middleware(e, request)
  File "/home/ec2-user/Virtual_Env/pinut_env/local/lib/python2.7/site-packages/django/core/handlers/base.py", line 147, in get_response
    response = wrapped_callback(request, *callback_args, **callback_kwargs)
  File "/home/ec2-user/Virtual_Env/DjangoCloudCode/DjangoCloudCode/pinutcloud/views.py", line 38, in getTotalFeedback
    cust_name=request.GET['cust_name']
  File "/home/ec2-user/Virtual_Env/pinut_env/local/lib/python2.7/site-packages/django/utils/datastructures.py", line 85, in __getitem__
    raise MultiValueDictKeyError(repr(key))
MultiValueDictKeyError: "'cust_name'"
[06/Jul/2016 14:28:03] DEBUG [pinutcloud.views:130] Inside processmongodata
[06/Jul/2016 14:28:03] DEBUG [pinutcloud.views:132] Inside GET request
[06/Jul/2016 14:28:03] ERROR [django.request:284] Internal Server Error: /pinutcloud/processUserInfoMongoData/
Traceback (most recent call last):
  File "/home/ec2-user/Virtual_Env/pinut_env/local/lib/python2.7/site-packages/django/core/handlers/base.py", line 149, in get_response
    response = self.process_exception_by_middleware(e, request)
  File "/home/ec2-user/Virtual_Env/pinut_env/local/lib/python2.7/site-packages/django/core/handlers/base.py", line 147, in get_response
    response = wrapped_callback(request, *callback_args, **callback_kwargs)
  File "/home/ec2-user/Virtual_Env/DjangoCloudCode/DjangoCloudCode/pinutcloud/views.py", line 133, in processUserInfoMongoData
    cust_name=request.GET['cust_name']
  File "/home/ec2-user/Virtual_Env/pinut_env/local/lib/python2.7/site-packages/django/utils/datastructures.py", line 85, in __getitem__
    raise MultiValueDictKeyError(repr(key))
MultiValueDictKeyError: "'cust_name'"
[06/Jul/2016 14:28:03] DEBUG [pinutcloud.views:52] Inside GET request
[06/Jul/2016 14:28:03] ERROR [django.request:284] Internal Server Error: /pinutcloud/getFeedbackRatings/
Traceback (most recent call last):
  File "/home/ec2-user/Virtual_Env/pinut_env/local/lib/python2.7/site-packages/django/core/handlers/base.py", line 149, in get_response
    response = self.process_exception_by_middleware(e, request)
  File "/home/ec2-user/Virtual_Env/pinut_env/local/lib/python2.7/site-packages/django/core/handlers/base.py", line 147, in get_response
    response = wrapped_callback(request, *callback_args, **callback_kwargs)
  File "/home/ec2-user/Virtual_Env/DjangoCloudCode/DjangoCloudCode/pinutcloud/views.py", line 53, in getFeedbackRatings
    cust_name=request.GET['cust_name']
  File "/home/ec2-user/Virtual_Env/pinut_env/local/lib/python2.7/site-packages/django/utils/datastructures.py", line 85, in __getitem__
    raise MultiValueDictKeyError(repr(key))
MultiValueDictKeyError: "'cust_name'"
[06/Jul/2016 14:28:03] DEBUG [pinutcloud.views:109] Inside GET request
[06/Jul/2016 14:28:03] ERROR [django.request:284] Internal Server Error: /pinutcloud/getUserIntroContent/
Traceback (most recent call last):
  File "/home/ec2-user/Virtual_Env/pinut_env/local/lib/python2.7/site-packages/django/core/handlers/base.py", line 149, in get_response
    response = self.process_exception_by_middleware(e, request)
  File "/home/ec2-user/Virtual_Env/pinut_env/local/lib/python2.7/site-packages/django/core/handlers/base.py", line 147, in get_response
    response = wrapped_callback(request, *callback_args, **callback_kwargs)
  File "/home/ec2-user/Virtual_Env/DjangoCloudCode/DjangoCloudCode/pinutcloud/views.py", line 110, in getUserIntroContent
    cust_name=request.GET['cust_name']
  File "/home/ec2-user/Virtual_Env/pinut_env/local/lib/python2.7/site-packages/django/utils/datastructures.py", line 85, in __getitem__
    raise MultiValueDictKeyError(repr(key))
MultiValueDictKeyError: "'cust_name'"
[06/Jul/2016 14:28:03] DEBUG [pinutcloud.views:67] Inside GET request
[06/Jul/2016 14:28:03] ERROR [django.request:284] Internal Server Error: /pinutcloud/getFeedbackContent/
Traceback (most recent call last):
  File "/home/ec2-user/Virtual_Env/pinut_env/local/lib/python2.7/site-packages/django/core/handlers/base.py", line 149, in get_response
    response = self.process_exception_by_middleware(e, request)
  File "/home/ec2-user/Virtual_Env/pinut_env/local/lib/python2.7/site-packages/django/core/handlers/base.py", line 147, in get_response
    response = wrapped_callback(request, *callback_args, **callback_kwargs)
  File "/home/ec2-user/Virtual_Env/DjangoCloudCode/DjangoCloudCode/pinutcloud/views.py", line 68, in getFeedbackContent
    cust_name=request.GET['cust_name']
  File "/home/ec2-user/Virtual_Env/pinut_env/local/lib/python2.7/site-packages/django/utils/datastructures.py", line 85, in __getitem__
    raise MultiValueDictKeyError(repr(key))
MultiValueDictKeyError: "'cust_name'"
[06/Jul/2016 14:34:51] DEBUG [pinutcloud.views:37] Inside GET request
[06/Jul/2016 14:34:51] DEBUG [pinutcloud.views:130] Inside processmongodata
[06/Jul/2016 14:34:51] DEBUG [pinutcloud.views:132] Inside GET request
[06/Jul/2016 14:34:51] DEBUG [pinutcloud.views:52] Inside GET request
[06/Jul/2016 14:34:52] DEBUG [pinutcloud.views:109] Inside GET request
[06/Jul/2016 14:34:52] DEBUG [pinutcloud.views:67] Inside GET request
[06/Jul/2016 14:39:24] DEBUG [pinutcloud.views:37] Inside GET request
[06/Jul/2016 14:39:24] DEBUG [pinutcloud.views:130] Inside processmongodata
[06/Jul/2016 14:39:24] DEBUG [pinutcloud.views:132] Inside GET request
[06/Jul/2016 14:39:24] DEBUG [pinutcloud.views:52] Inside GET request
[06/Jul/2016 14:39:25] DEBUG [pinutcloud.views:109] Inside GET request
[06/Jul/2016 14:39:25] DEBUG [pinutcloud.views:67] Inside GET request
[06/Jul/2016 14:39:54] ERROR [django.request:284] Internal Server Error: /pinutcloud/getTotalDownloads/
Traceback (most recent call last):
  File "/home/ec2-user/Virtual_Env/pinut_env/local/lib/python2.7/site-packages/django/core/handlers/base.py", line 149, in get_response
    response = self.process_exception_by_middleware(e, request)
  File "/home/ec2-user/Virtual_Env/pinut_env/local/lib/python2.7/site-packages/django/core/handlers/base.py", line 147, in get_response
    response = wrapped_callback(request, *callback_args, **callback_kwargs)
  File "/home/ec2-user/Virtual_Env/DjangoCloudCode/DjangoCloudCode/pinutcloud/views.py", line 87, in getTotalDownloads
    cust_name=request.GET['cust_name']
  File "/home/ec2-user/Virtual_Env/pinut_env/local/lib/python2.7/site-packages/django/utils/datastructures.py", line 85, in __getitem__
    raise MultiValueDictKeyError(repr(key))
MultiValueDictKeyError: "'cust_name'"
[06/Jul/2016 14:39:54] DEBUG [pinutcloud.views:37] Inside GET request
[06/Jul/2016 14:39:54] ERROR [django.request:284] Internal Server Error: /pinutcloud/getTotalFeedback/
Traceback (most recent call last):
  File "/home/ec2-user/Virtual_Env/pinut_env/local/lib/python2.7/site-packages/django/core/handlers/base.py", line 149, in get_response
    response = self.process_exception_by_middleware(e, request)
  File "/home/ec2-user/Virtual_Env/pinut_env/local/lib/python2.7/site-packages/django/core/handlers/base.py", line 147, in get_response
    response = wrapped_callback(request, *callback_args, **callback_kwargs)
  File "/home/ec2-user/Virtual_Env/DjangoCloudCode/DjangoCloudCode/pinutcloud/views.py", line 38, in getTotalFeedback
    cust_name=request.GET['cust_name']
  File "/home/ec2-user/Virtual_Env/pinut_env/local/lib/python2.7/site-packages/django/utils/datastructures.py", line 85, in __getitem__
    raise MultiValueDictKeyError(repr(key))
MultiValueDictKeyError: "'cust_name'"
[06/Jul/2016 14:39:55] DEBUG [pinutcloud.views:130] Inside processmongodata
[06/Jul/2016 14:39:55] DEBUG [pinutcloud.views:132] Inside GET request
[06/Jul/2016 14:39:55] ERROR [django.request:284] Internal Server Error: /pinutcloud/processUserInfoMongoData/
Traceback (most recent call last):
  File "/home/ec2-user/Virtual_Env/pinut_env/local/lib/python2.7/site-packages/django/core/handlers/base.py", line 149, in get_response
    response = self.process_exception_by_middleware(e, request)
  File "/home/ec2-user/Virtual_Env/pinut_env/local/lib/python2.7/site-packages/django/core/handlers/base.py", line 147, in get_response
    response = wrapped_callback(request, *callback_args, **callback_kwargs)
  File "/home/ec2-user/Virtual_Env/DjangoCloudCode/DjangoCloudCode/pinutcloud/views.py", line 133, in processUserInfoMongoData
    cust_name=request.GET['cust_name']
  File "/home/ec2-user/Virtual_Env/pinut_env/local/lib/python2.7/site-packages/django/utils/datastructures.py", line 85, in __getitem__
    raise MultiValueDictKeyError(repr(key))
MultiValueDictKeyError: "'cust_name'"
[06/Jul/2016 14:39:55] DEBUG [pinutcloud.views:52] Inside GET request
[06/Jul/2016 14:39:55] ERROR [django.request:284] Internal Server Error: /pinutcloud/getFeedbackRatings/
Traceback (most recent call last):
  File "/home/ec2-user/Virtual_Env/pinut_env/local/lib/python2.7/site-packages/django/core/handlers/base.py", line 149, in get_response
    response = self.process_exception_by_middleware(e, request)
  File "/home/ec2-user/Virtual_Env/pinut_env/local/lib/python2.7/site-packages/django/core/handlers/base.py", line 147, in get_response
    response = wrapped_callback(request, *callback_args, **callback_kwargs)
  File "/home/ec2-user/Virtual_Env/DjangoCloudCode/DjangoCloudCode/pinutcloud/views.py", line 53, in getFeedbackRatings
    cust_name=request.GET['cust_name']
  File "/home/ec2-user/Virtual_Env/pinut_env/local/lib/python2.7/site-packages/django/utils/datastructures.py", line 85, in __getitem__
    raise MultiValueDictKeyError(repr(key))
MultiValueDictKeyError: "'cust_name'"
[06/Jul/2016 14:39:55] DEBUG [pinutcloud.views:109] Inside GET request
[06/Jul/2016 14:39:55] ERROR [django.request:284] Internal Server Error: /pinutcloud/getUserIntroContent/
Traceback (most recent call last):
  File "/home/ec2-user/Virtual_Env/pinut_env/local/lib/python2.7/site-packages/django/core/handlers/base.py", line 149, in get_response
    response = self.process_exception_by_middleware(e, request)
  File "/home/ec2-user/Virtual_Env/pinut_env/local/lib/python2.7/site-packages/django/core/handlers/base.py", line 147, in get_response
    response = wrapped_callback(request, *callback_args, **callback_kwargs)
  File "/home/ec2-user/Virtual_Env/DjangoCloudCode/DjangoCloudCode/pinutcloud/views.py", line 110, in getUserIntroContent
    cust_name=request.GET['cust_name']
  File "/home/ec2-user/Virtual_Env/pinut_env/local/lib/python2.7/site-packages/django/utils/datastructures.py", line 85, in __getitem__
    raise MultiValueDictKeyError(repr(key))
MultiValueDictKeyError: "'cust_name'"
[06/Jul/2016 14:39:55] DEBUG [pinutcloud.views:67] Inside GET request
[06/Jul/2016 14:39:55] ERROR [django.request:284] Internal Server Error: /pinutcloud/getFeedbackContent/
Traceback (most recent call last):
  File "/home/ec2-user/Virtual_Env/pinut_env/local/lib/python2.7/site-packages/django/core/handlers/base.py", line 149, in get_response
    response = self.process_exception_by_middleware(e, request)
  File "/home/ec2-user/Virtual_Env/pinut_env/local/lib/python2.7/site-packages/django/core/handlers/base.py", line 147, in get_response
    response = wrapped_callback(request, *callback_args, **callback_kwargs)
  File "/home/ec2-user/Virtual_Env/DjangoCloudCode/DjangoCloudCode/pinutcloud/views.py", line 68, in getFeedbackContent
    cust_name=request.GET['cust_name']
  File "/home/ec2-user/Virtual_Env/pinut_env/local/lib/python2.7/site-packages/django/utils/datastructures.py", line 85, in __getitem__
    raise MultiValueDictKeyError(repr(key))
MultiValueDictKeyError: "'cust_name'"
[06/Jul/2016 14:40:13] DEBUG [pinutcloud.views:37] Inside GET request
[06/Jul/2016 14:40:14] DEBUG [pinutcloud.views:130] Inside processmongodata
[06/Jul/2016 14:40:14] DEBUG [pinutcloud.views:132] Inside GET request
[06/Jul/2016 14:40:14] DEBUG [pinutcloud.views:52] Inside GET request
[06/Jul/2016 14:40:14] DEBUG [pinutcloud.views:109] Inside GET request
[06/Jul/2016 14:40:14] DEBUG [pinutcloud.views:67] Inside GET request
[06/Jul/2016 14:40:25] DEBUG [pinutcloud.views:37] Inside GET request
[06/Jul/2016 14:40:25] DEBUG [pinutcloud.views:130] Inside processmongodata
[06/Jul/2016 14:40:25] DEBUG [pinutcloud.views:132] Inside GET request
[06/Jul/2016 14:40:25] DEBUG [pinutcloud.views:52] Inside GET request
[06/Jul/2016 14:40:25] DEBUG [pinutcloud.views:109] Inside GET request
[06/Jul/2016 14:40:26] DEBUG [pinutcloud.views:67] Inside GET request
[06/Jul/2016 14:40:35] DEBUG [pinutcloud.views:37] Inside GET request
[06/Jul/2016 14:40:35] DEBUG [pinutcloud.views:130] Inside processmongodata
[06/Jul/2016 14:40:35] DEBUG [pinutcloud.views:132] Inside GET request
[06/Jul/2016 14:40:35] DEBUG [pinutcloud.views:52] Inside GET request
[06/Jul/2016 14:40:36] DEBUG [pinutcloud.views:109] Inside GET request
[06/Jul/2016 14:40:36] DEBUG [pinutcloud.views:67] Inside GET request
[06/Jul/2016 14:40:55] DEBUG [pinutcloud.views:37] Inside GET request
[06/Jul/2016 14:40:56] DEBUG [pinutcloud.views:130] Inside processmongodata
[06/Jul/2016 14:40:56] DEBUG [pinutcloud.views:132] Inside GET request
[06/Jul/2016 14:40:56] DEBUG [pinutcloud.views:52] Inside GET request
[06/Jul/2016 14:40:56] DEBUG [pinutcloud.views:109] Inside GET request
[06/Jul/2016 14:40:56] DEBUG [pinutcloud.views:67] Inside GET request
[06/Jul/2016 14:41:05] DEBUG [pinutcloud.views:37] Inside GET request
[06/Jul/2016 14:41:05] DEBUG [pinutcloud.views:130] Inside processmongodata
[06/Jul/2016 14:41:05] DEBUG [pinutcloud.views:132] Inside GET request
[06/Jul/2016 14:41:05] DEBUG [pinutcloud.views:52] Inside GET request
[06/Jul/2016 14:41:06] DEBUG [pinutcloud.views:109] Inside GET request
[06/Jul/2016 14:41:06] DEBUG [pinutcloud.views:67] Inside GET request
[06/Jul/2016 14:57:47] DEBUG [pinutcloud.views:37] Inside GET request
[06/Jul/2016 14:57:47] DEBUG [pinutcloud.views:130] Inside processmongodata
[06/Jul/2016 14:57:47] DEBUG [pinutcloud.views:132] Inside GET request
[06/Jul/2016 14:57:47] DEBUG [pinutcloud.views:52] Inside GET request
[06/Jul/2016 14:57:48] DEBUG [pinutcloud.views:109] Inside GET request
[06/Jul/2016 14:57:48] DEBUG [pinutcloud.views:67] Inside GET request
